[2024-11-29T21:06:06.508+0000] {local_task_job_runner.py:120} INFO - ::group::Pre task execution logs
[2024-11-29T21:06:06.535+0000] {taskinstance.py:2076} INFO - Dependencies all met for dep_context=non-requeueable deps ti=<TaskInstance: weather_data_kafka_dag.store_openweathermap_data manual__2024-11-29T20:52:23.635430+00:00 [queued]>
[2024-11-29T21:06:06.544+0000] {taskinstance.py:2076} INFO - Dependencies all met for dep_context=requeueable deps ti=<TaskInstance: weather_data_kafka_dag.store_openweathermap_data manual__2024-11-29T20:52:23.635430+00:00 [queued]>
[2024-11-29T21:06:06.546+0000] {taskinstance.py:2306} INFO - Starting attempt 3 of 4
[2024-11-29T21:06:06.559+0000] {taskinstance.py:2330} INFO - Executing <Task(PythonOperator): store_openweathermap_data> on 2024-11-29 20:52:23.635430+00:00
[2024-11-29T21:06:06.566+0000] {logging_mixin.py:188} WARNING - /home/***/.local/lib/python3.12/site-packages/***/task/task_runner/standard_task_runner.py:62 DeprecationWarning: This process (pid=11132) is multi-threaded, use of fork() may lead to deadlocks in the child.
[2024-11-29T21:06:06.568+0000] {standard_task_runner.py:64} INFO - Started process 11138 to run task
[2024-11-29T21:06:06.567+0000] {standard_task_runner.py:90} INFO - Running: ['***', 'tasks', 'run', 'weather_data_kafka_dag', 'store_openweathermap_data', 'manual__2024-11-29T20:52:23.635430+00:00', '--job-id', '322', '--raw', '--subdir', 'DAGS_FOLDER/kafka_stream.py', '--cfg-path', '/tmp/tmpowb7diwk']
[2024-11-29T21:06:06.569+0000] {standard_task_runner.py:91} INFO - Job 322: Subtask store_openweathermap_data
[2024-11-29T21:06:06.609+0000] {task_command.py:426} INFO - Running <TaskInstance: weather_data_kafka_dag.store_openweathermap_data manual__2024-11-29T20:52:23.635430+00:00 [running]> on host 0741a2a1545f
[2024-11-29T21:06:06.681+0000] {taskinstance.py:2648} INFO - Exporting env vars: AIRFLOW_CTX_DAG_OWNER='admin' AIRFLOW_CTX_DAG_ID='weather_data_kafka_dag' AIRFLOW_CTX_TASK_ID='store_openweathermap_data' AIRFLOW_CTX_EXECUTION_DATE='2024-11-29T20:52:23.635430+00:00' AIRFLOW_CTX_TRY_NUMBER='3' AIRFLOW_CTX_DAG_RUN_ID='manual__2024-11-29T20:52:23.635430+00:00'
[2024-11-29T21:06:06.682+0000] {taskinstance.py:430} INFO - ::endgroup::
[2024-11-29T21:06:06.691+0000] {taskinstance.py:441} INFO - ::group::Post task execution logs
[2024-11-29T21:06:06.692+0000] {taskinstance.py:2905} ERROR - Task failed with exception
Traceback (most recent call last):
  File "/home/airflow/.local/lib/python3.12/site-packages/airflow/models/taskinstance.py", line 465, in _execute_task
    result = _execute_callable(context=context, **execute_callable_kwargs)
             ^^^^^^^^^^^^^^^^^^^^^^^^^^^^^^^^^^^^^^^^^^^^^^^^^^^^^^^^^^^^^
  File "/home/airflow/.local/lib/python3.12/site-packages/airflow/models/taskinstance.py", line 432, in _execute_callable
    return execute_callable(context=context, **execute_callable_kwargs)
           ^^^^^^^^^^^^^^^^^^^^^^^^^^^^^^^^^^^^^^^^^^^^^^^^^^^^^^^^^^^^
  File "/home/airflow/.local/lib/python3.12/site-packages/airflow/models/baseoperator.py", line 401, in wrapper
    return func(self, *args, **kwargs)
           ^^^^^^^^^^^^^^^^^^^^^^^^^^^
  File "/home/airflow/.local/lib/python3.12/site-packages/airflow/operators/python.py", line 235, in execute
    return_value = self.execute_callable()
                   ^^^^^^^^^^^^^^^^^^^^^^^
  File "/home/airflow/.local/lib/python3.12/site-packages/airflow/operators/python.py", line 252, in execute_callable
    return self.python_callable(*self.op_args, **self.op_kwargs)
           ^^^^^^^^^^^^^^^^^^^^^^^^^^^^^^^^^^^^^^^^^^^^^^^^^^^^^
  File "/opt/airflow/dags/kafka_stream.py", line 146, in store_openweathermap_data
    read_from_kafka_and_store(KAFKA_TOPIC_OPENWEATHER, "openweathermap_data.parquet")
  File "/opt/airflow/dags/kafka_stream.py", line 141, in read_from_kafka_and_store
    logging.error(f"Error reading from Kafka topic {topic_name}: {e}")
                                                                  ^
NameError: name 'e' is not defined
[2024-11-29T21:06:06.702+0000] {taskinstance.py:1206} INFO - Marking task as UP_FOR_RETRY. dag_id=weather_data_kafka_dag, task_id=store_openweathermap_data, run_id=manual__2024-11-29T20:52:23.635430+00:00, execution_date=20241129T205223, start_date=20241129T210606, end_date=20241129T210606
[2024-11-29T21:06:06.715+0000] {standard_task_runner.py:110} ERROR - Failed to execute job 322 for task store_openweathermap_data (name 'e' is not defined; 11138)
[2024-11-29T21:06:06.742+0000] {local_task_job_runner.py:243} INFO - Task exited with return code 1
[2024-11-29T21:06:06.756+0000] {taskinstance.py:3503} INFO - 0 downstream tasks scheduled from follow-on schedule check
[2024-11-29T21:06:06.759+0000] {local_task_job_runner.py:222} INFO - ::endgroup::
