[2024-12-01T19:20:56.236+0000] {local_task_job_runner.py:120} INFO - ::group::Pre task execution logs
[2024-12-01T19:20:56.300+0000] {taskinstance.py:2076} INFO - Dependencies all met for dep_context=non-requeueable deps ti=<TaskInstance: weather_data_kafka_dag.store_openweathermap_data manual__2024-12-01T19:20:22.100845+00:00 [queued]>
[2024-12-01T19:20:56.319+0000] {taskinstance.py:2076} INFO - Dependencies all met for dep_context=requeueable deps ti=<TaskInstance: weather_data_kafka_dag.store_openweathermap_data manual__2024-12-01T19:20:22.100845+00:00 [queued]>
[2024-12-01T19:20:56.326+0000] {taskinstance.py:2306} INFO - Starting attempt 1 of 4
[2024-12-01T19:20:56.360+0000] {taskinstance.py:2330} INFO - Executing <Task(PythonOperator): store_openweathermap_data> on 2024-12-01 19:20:22.100845+00:00
[2024-12-01T19:20:56.374+0000] {standard_task_runner.py:90} INFO - Running: ['***', 'tasks', 'run', 'weather_data_kafka_dag', 'store_openweathermap_data', 'manual__2024-12-01T19:20:22.100845+00:00', '--job-id', '570', '--raw', '--subdir', 'DAGS_FOLDER/kafka_stream.py', '--cfg-path', '/tmp/tmpah3jsi4w']
[2024-12-01T19:20:56.380+0000] {standard_task_runner.py:91} INFO - Job 570: Subtask store_openweathermap_data
[2024-12-01T19:20:56.384+0000] {logging_mixin.py:188} WARNING - /home/***/.local/lib/python3.12/site-packages/***/task/task_runner/standard_task_runner.py:62 DeprecationWarning: This process (pid=7180) is multi-threaded, use of fork() may lead to deadlocks in the child.
[2024-12-01T19:20:56.386+0000] {standard_task_runner.py:64} INFO - Started process 7185 to run task
[2024-12-01T19:20:56.463+0000] {task_command.py:426} INFO - Running <TaskInstance: weather_data_kafka_dag.store_openweathermap_data manual__2024-12-01T19:20:22.100845+00:00 [running]> on host 0741a2a1545f
[2024-12-01T19:20:56.683+0000] {taskinstance.py:2648} INFO - Exporting env vars: AIRFLOW_CTX_DAG_OWNER='admin' AIRFLOW_CTX_DAG_ID='weather_data_kafka_dag' AIRFLOW_CTX_TASK_ID='store_openweathermap_data' AIRFLOW_CTX_EXECUTION_DATE='2024-12-01T19:20:22.100845+00:00' AIRFLOW_CTX_TRY_NUMBER='1' AIRFLOW_CTX_DAG_RUN_ID='manual__2024-12-01T19:20:22.100845+00:00'
[2024-12-01T19:20:56.685+0000] {taskinstance.py:430} INFO - ::endgroup::
[2024-12-01T19:20:56.709+0000] {conn.py:362} INFO - <BrokerConnection node_id=bootstrap-0 host=broker:9092 <connecting> [IPv4 ('172.18.0.11', 9092)]>: connecting to broker:9092 [('172.18.0.11', 9092) IPv4]
[2024-12-01T19:20:56.710+0000] {conn.py:957} INFO - Probing node bootstrap-0 broker version
[2024-12-01T19:20:56.712+0000] {conn.py:393} INFO - <BrokerConnection node_id=bootstrap-0 host=broker:9092 <connecting> [IPv4 ('172.18.0.11', 9092)]>: Connection complete.
[2024-12-01T19:20:56.820+0000] {conn.py:1019} INFO - Broker version identified as 2.6.0
[2024-12-01T19:20:56.821+0000] {conn.py:1020} INFO - Set configuration api_version=(2, 6, 0) to skip auto check_version requests on startup
[2024-12-01T19:20:56.827+0000] {consumer.py:122} WARNING - group_id is None: disabling auto-commit.
[2024-12-01T19:20:56.830+0000] {subscription_state.py:167} INFO - Updating subscribed topics to: ('openweathermap_raw',)
[2024-12-01T19:20:56.837+0000] {subscription_state.py:253} INFO - Updated partition assignment: [('openweathermap_raw', 0)]
[2024-12-01T19:20:56.844+0000] {conn.py:362} INFO - <BrokerConnection node_id=1 host=broker:9092 <connecting> [IPv4 ('172.18.0.11', 9092)]>: connecting to broker:9092 [('172.18.0.11', 9092) IPv4]
[2024-12-01T19:20:56.846+0000] {conn.py:393} INFO - <BrokerConnection node_id=1 host=broker:9092 <connecting> [IPv4 ('172.18.0.11', 9092)]>: Connection complete.
[2024-12-01T19:20:56.848+0000] {conn.py:673} INFO - <BrokerConnection node_id=bootstrap-0 host=broker:9092 <connected> [IPv4 ('172.18.0.11', 9092)]>: Closing connection. 
[2024-12-01T19:39:33.415+0000] {fetcher.py:847} INFO - Fetch offset 37 is out of range for topic-partition ('openweathermap_raw', 0)
[2024-12-01T21:38:08.459+0000] {local_task_job_runner.py:313} WARNING - State of this instance has been externally set to None. Terminating instance.
[2024-12-01T21:38:08.484+0000] {local_task_job_runner.py:222} INFO - ::endgroup::
[2024-12-01T21:38:08.489+0000] {process_utils.py:132} INFO - Sending 15 to group 7185. PIDs of all processes in the group: [7185]
[2024-12-01T21:38:08.490+0000] {process_utils.py:87} INFO - Sending the signal 15 to group 7185
[2024-12-01T21:38:08.494+0000] {taskinstance.py:2611} ERROR - Received SIGTERM. Terminating subprocesses.
[2024-12-01T21:38:08.506+0000] {taskinstance.py:441} INFO - ::group::Post task execution logs
[2024-12-01T21:38:08.587+0000] {taskinstance.py:2905} ERROR - Task failed with exception
Traceback (most recent call last):
  File "/home/airflow/.local/lib/python3.12/site-packages/airflow/models/taskinstance.py", line 465, in _execute_task
    result = _execute_callable(context=context, **execute_callable_kwargs)
             ^^^^^^^^^^^^^^^^^^^^^^^^^^^^^^^^^^^^^^^^^^^^^^^^^^^^^^^^^^^^^
  File "/home/airflow/.local/lib/python3.12/site-packages/airflow/models/taskinstance.py", line 432, in _execute_callable
    return execute_callable(context=context, **execute_callable_kwargs)
           ^^^^^^^^^^^^^^^^^^^^^^^^^^^^^^^^^^^^^^^^^^^^^^^^^^^^^^^^^^^^
  File "/home/airflow/.local/lib/python3.12/site-packages/airflow/models/baseoperator.py", line 401, in wrapper
    return func(self, *args, **kwargs)
           ^^^^^^^^^^^^^^^^^^^^^^^^^^^
  File "/home/airflow/.local/lib/python3.12/site-packages/airflow/operators/python.py", line 235, in execute
    return_value = self.execute_callable()
                   ^^^^^^^^^^^^^^^^^^^^^^^
  File "/home/airflow/.local/lib/python3.12/site-packages/airflow/operators/python.py", line 252, in execute_callable
    return self.python_callable(*self.op_args, **self.op_kwargs)
           ^^^^^^^^^^^^^^^^^^^^^^^^^^^^^^^^^^^^^^^^^^^^^^^^^^^^^
  File "/opt/airflow/dags/kafka_stream.py", line 187, in store_openweathermap_data
    # Log the number of records consumed
  File "/opt/airflow/dags/kafka_stream.py", line 157, in read_from_kafka_and_store
    fetch_openweathermap_data(city)
  File "/home/airflow/.local/lib/python3.12/site-packages/kafka/consumer/group.py", line 1203, in __next__
    return self.next_v2()
           ^^^^^^^^^^^^^^
  File "/home/airflow/.local/lib/python3.12/site-packages/kafka/consumer/group.py", line 1211, in next_v2
    return next(self._iterator)
           ^^^^^^^^^^^^^^^^^^^^
  File "/home/airflow/.local/lib/python3.12/site-packages/kafka/consumer/group.py", line 1126, in _message_generator_v2
    record_map = self.poll(timeout_ms=timeout_ms, update_offsets=False)
                 ^^^^^^^^^^^^^^^^^^^^^^^^^^^^^^^^^^^^^^^^^^^^^^^^^^^^^^
  File "/home/airflow/.local/lib/python3.12/site-packages/kafka/consumer/group.py", line 663, in poll
    records = self._poll_once(remaining, max_records, update_offsets=update_offsets)
              ^^^^^^^^^^^^^^^^^^^^^^^^^^^^^^^^^^^^^^^^^^^^^^^^^^^^^^^^^^^^^^^^^^^^^^
  File "/home/airflow/.local/lib/python3.12/site-packages/kafka/consumer/group.py", line 712, in _poll_once
    self._client.poll(timeout_ms=timeout_ms)
  File "/home/airflow/.local/lib/python3.12/site-packages/kafka/client_async.py", line 601, in poll
    self._poll(timeout / 1000)
  File "/home/airflow/.local/lib/python3.12/site-packages/kafka/client_async.py", line 633, in _poll
    ready = self._selector.select(timeout)
            ^^^^^^^^^^^^^^^^^^^^^^^^^^^^^^
  File "/usr/local/lib/python3.12/selectors.py", line 468, in select
    fd_event_list = self._selector.poll(timeout, max_ev)
                    ^^^^^^^^^^^^^^^^^^^^^^^^^^^^^^^^^^^^
  File "/home/airflow/.local/lib/python3.12/site-packages/airflow/models/taskinstance.py", line 2613, in signal_handler
    raise AirflowTaskTerminated("Task received SIGTERM signal")
airflow.exceptions.AirflowTaskTerminated: Task received SIGTERM signal
[2024-12-01T21:38:08.615+0000] {taskinstance.py:1206} INFO - Marking task as UP_FOR_RETRY. dag_id=weather_data_kafka_dag, task_id=store_openweathermap_data, run_id=manual__2024-12-01T19:20:22.100845+00:00, execution_date=20241201T192022, start_date=20241201T192056, end_date=20241201T213808
[2024-12-01T21:38:08.673+0000] {standard_task_runner.py:110} ERROR - Failed to execute job 570 for task store_openweathermap_data ((psycopg2.errors.ForeignKeyViolation) insert or update on table "task_fail" violates foreign key constraint "task_fail_ti_fkey"
DETAIL:  Key (dag_id, task_id, run_id, map_index)=(weather_data_kafka_dag, store_openweathermap_data, manual__2024-12-01T19:20:22.100845+00:00, -1) is not present in table "task_instance".

[SQL: INSERT INTO task_fail (task_id, dag_id, run_id, map_index, start_date, end_date, duration) VALUES (%(task_id)s, %(dag_id)s, %(run_id)s, %(map_index)s, %(start_date)s, %(end_date)s, %(duration)s) RETURNING task_fail.id]
[parameters: {'task_id': 'store_openweathermap_data', 'dag_id': 'weather_data_kafka_dag', 'run_id': 'manual__2024-12-01T19:20:22.100845+00:00', 'map_index': -1, 'start_date': datetime.datetime(2024, 12, 1, 19, 20, 56, 301666, tzinfo=Timezone('UTC')), 'end_date': datetime.datetime(2024, 12, 1, 21, 38, 8, 607058, tzinfo=Timezone('UTC')), 'duration': 8232}]
(Background on this error at: https://sqlalche.me/e/14/gkpj); 7185)
[2024-12-01T21:38:08.704+0000] {process_utils.py:80} INFO - Process psutil.Process(pid=7185, status='terminated', exitcode=1, started='19:20:55') (7185) terminated with exit code 1
