[2024-12-01T05:06:16.572+0000] {local_task_job_runner.py:120} INFO - ::group::Pre task execution logs
[2024-12-01T05:06:16.783+0000] {taskinstance.py:2076} INFO - Dependencies all met for dep_context=non-requeueable deps ti=<TaskInstance: weather_data_kafka_dag.stream_data_from_apis scheduled__2024-11-30T23:00:00+00:00 [queued]>
[2024-12-01T05:06:16.853+0000] {taskinstance.py:2076} INFO - Dependencies all met for dep_context=requeueable deps ti=<TaskInstance: weather_data_kafka_dag.stream_data_from_apis scheduled__2024-11-30T23:00:00+00:00 [queued]>
[2024-12-01T05:06:16.859+0000] {taskinstance.py:2306} INFO - Starting attempt 1 of 4
[2024-12-01T05:06:16.962+0000] {taskinstance.py:2330} INFO - Executing <Task(PythonOperator): stream_data_from_apis> on 2024-11-30 23:00:00+00:00
[2024-12-01T05:06:17.016+0000] {logging_mixin.py:188} WARNING - /home/***/.local/lib/python3.12/site-packages/***/task/task_runner/standard_task_runner.py:62 DeprecationWarning: This process (pid=20567) is multi-threaded, use of fork() may lead to deadlocks in the child.
[2024-12-01T05:06:17.025+0000] {standard_task_runner.py:90} INFO - Running: ['***', 'tasks', 'run', 'weather_data_kafka_dag', 'stream_data_from_apis', 'scheduled__2024-11-30T23:00:00+00:00', '--job-id', '500', '--raw', '--subdir', 'DAGS_FOLDER/kafka_stream.py', '--cfg-path', '/tmp/tmpmca2fd7y']
[2024-12-01T05:06:17.045+0000] {standard_task_runner.py:64} INFO - Started process 20577 to run task
[2024-12-01T05:06:17.077+0000] {standard_task_runner.py:91} INFO - Job 500: Subtask stream_data_from_apis
[2024-12-01T05:06:17.450+0000] {task_command.py:426} INFO - Running <TaskInstance: weather_data_kafka_dag.stream_data_from_apis scheduled__2024-11-30T23:00:00+00:00 [running]> on host 0741a2a1545f
[2024-12-01T05:06:18.186+0000] {taskinstance.py:2648} INFO - Exporting env vars: AIRFLOW_CTX_DAG_OWNER='admin' AIRFLOW_CTX_DAG_ID='weather_data_kafka_dag' AIRFLOW_CTX_TASK_ID='stream_data_from_apis' AIRFLOW_CTX_EXECUTION_DATE='2024-11-30T23:00:00+00:00' AIRFLOW_CTX_TRY_NUMBER='1' AIRFLOW_CTX_DAG_RUN_ID='scheduled__2024-11-30T23:00:00+00:00'
[2024-12-01T05:06:18.196+0000] {taskinstance.py:430} INFO - ::endgroup::
[2024-12-01T05:06:18.310+0000] {conn.py:362} INFO - <BrokerConnection node_id=bootstrap-0 host=broker:9092 <connecting> [IPv4 ('172.18.0.8', 9092)]>: connecting to broker:9092 [('172.18.0.8', 9092) IPv4]
[2024-12-01T05:06:18.318+0000] {conn.py:957} INFO - Probing node bootstrap-0 broker version
[2024-12-01T05:06:18.320+0000] {conn.py:393} INFO - <BrokerConnection node_id=bootstrap-0 host=broker:9092 <connecting> [IPv4 ('172.18.0.8', 9092)]>: Connection complete.
[2024-12-01T05:06:18.428+0000] {conn.py:1019} INFO - Broker version identified as 2.6.0
[2024-12-01T05:06:18.440+0000] {conn.py:1020} INFO - Set configuration api_version=(2, 6, 0) to skip auto check_version requests on startup
[2024-12-01T05:06:18.490+0000] {kafka_stream.py:94} ERROR - Erreur lors de la récupération des données d'OpenWeatherMap pour Casablanca: HTTPConnectionPool(host='api.openweathermap.org', port=80): Max retries exceeded with url: /data/2.5/weather?q=Casablanca%2Cma&appid=8167e2dfee0bd9f28f8eafbd9e355ad3&units=metric (Caused by NameResolutionError("<urllib3.connection.HTTPConnection object at 0x7f9c7a2b7b90>: Failed to resolve 'api.openweathermap.org' ([Errno -2] Name or service not known)"))
[2024-12-01T05:06:18.507+0000] {kafka_stream.py:119} ERROR - Erreur lors de la récupération des données d'Open-Meteo pour Casablanca: HTTPSConnectionPool(host='api.open-meteo.com', port=443): Max retries exceeded with url: /v1/forecast?latitude=33.5945144&longitude=-7.6200284&current=temperature_2m%2Crelative_humidity_2m%2Capparent_temperature%2Cis_day%2Cprecipitation%2Crain%2Cshowers%2Csnowfall%2Cweather_code%2Ccloud_cover%2Cpressure_msl%2Csurface_pressure (Caused by NameResolutionError("<urllib3.connection.HTTPSConnection object at 0x7f9c7a2f0830>: Failed to resolve 'api.open-meteo.com' ([Errno -2] Name or service not known)"))
[2024-12-01T05:06:18.522+0000] {kafka_stream.py:94} ERROR - Erreur lors de la récupération des données d'OpenWeatherMap pour Rabat: HTTPConnectionPool(host='api.openweathermap.org', port=80): Max retries exceeded with url: /data/2.5/weather?q=Rabat%2Cma&appid=8167e2dfee0bd9f28f8eafbd9e355ad3&units=metric (Caused by NameResolutionError("<urllib3.connection.HTTPConnection object at 0x7f9c7a5e6ba0>: Failed to resolve 'api.openweathermap.org' ([Errno -2] Name or service not known)"))
[2024-12-01T05:06:18.541+0000] {kafka_stream.py:119} ERROR - Erreur lors de la récupération des données d'Open-Meteo pour Rabat: HTTPSConnectionPool(host='api.open-meteo.com', port=443): Max retries exceeded with url: /v1/forecast?latitude=34.02236&longitude=-6.8340222&current=temperature_2m%2Crelative_humidity_2m%2Capparent_temperature%2Cis_day%2Cprecipitation%2Crain%2Cshowers%2Csnowfall%2Cweather_code%2Ccloud_cover%2Cpressure_msl%2Csurface_pressure (Caused by NameResolutionError("<urllib3.connection.HTTPSConnection object at 0x7f9c7a2f2510>: Failed to resolve 'api.open-meteo.com' ([Errno -2] Name or service not known)"))
[2024-12-01T05:06:18.569+0000] {kafka_stream.py:94} ERROR - Erreur lors de la récupération des données d'OpenWeatherMap pour Fès: HTTPConnectionPool(host='api.openweathermap.org', port=80): Max retries exceeded with url: /data/2.5/weather?q=F%C3%A8s%2Cma&appid=8167e2dfee0bd9f28f8eafbd9e355ad3&units=metric (Caused by NameResolutionError("<urllib3.connection.HTTPConnection object at 0x7f9c7a2f3410>: Failed to resolve 'api.openweathermap.org' ([Errno -2] Name or service not known)"))
[2024-12-01T05:06:18.585+0000] {kafka_stream.py:119} ERROR - Erreur lors de la récupération des données d'Open-Meteo pour Fès: HTTPSConnectionPool(host='api.open-meteo.com', port=443): Max retries exceeded with url: /v1/forecast?latitude=34.0346534&longitude=-5.0161926&current=temperature_2m%2Crelative_humidity_2m%2Capparent_temperature%2Cis_day%2Cprecipitation%2Crain%2Cshowers%2Csnowfall%2Cweather_code%2Ccloud_cover%2Cpressure_msl%2Csurface_pressure (Caused by NameResolutionError("<urllib3.connection.HTTPSConnection object at 0x7f9c7a2f3f50>: Failed to resolve 'api.open-meteo.com' ([Errno -2] Name or service not known)"))
[2024-12-01T05:06:18.612+0000] {kafka_stream.py:94} ERROR - Erreur lors de la récupération des données d'OpenWeatherMap pour Marrakech: HTTPConnectionPool(host='api.openweathermap.org', port=80): Max retries exceeded with url: /data/2.5/weather?q=Marrakech%2Cma&appid=8167e2dfee0bd9f28f8eafbd9e355ad3&units=metric (Caused by NameResolutionError("<urllib3.connection.HTTPConnection object at 0x7f9c7a3407a0>: Failed to resolve 'api.openweathermap.org' ([Errno -2] Name or service not known)"))
[2024-12-01T05:06:18.631+0000] {kafka_stream.py:119} ERROR - Erreur lors de la récupération des données d'Open-Meteo pour Marrakech: HTTPSConnectionPool(host='api.open-meteo.com', port=443): Max retries exceeded with url: /v1/forecast?latitude=31.6258257&longitude=-7.9891608&current=temperature_2m%2Crelative_humidity_2m%2Capparent_temperature%2Cis_day%2Cprecipitation%2Crain%2Cshowers%2Csnowfall%2Cweather_code%2Ccloud_cover%2Cpressure_msl%2Csurface_pressure (Caused by NameResolutionError("<urllib3.connection.HTTPSConnection object at 0x7f9c7a341070>: Failed to resolve 'api.open-meteo.com' ([Errno -2] Name or service not known)"))
[2024-12-01T05:06:18.640+0000] {kafka_stream.py:94} ERROR - Erreur lors de la récupération des données d'OpenWeatherMap pour Agadir: HTTPConnectionPool(host='api.openweathermap.org', port=80): Max retries exceeded with url: /data/2.5/weather?q=Agadir%2Cma&appid=8167e2dfee0bd9f28f8eafbd9e355ad3&units=metric (Caused by NameResolutionError("<urllib3.connection.HTTPConnection object at 0x7f9c7a2f3230>: Failed to resolve 'api.openweathermap.org' ([Errno -2] Name or service not known)"))
[2024-12-01T05:06:18.674+0000] {kafka_stream.py:119} ERROR - Erreur lors de la récupération des données d'Open-Meteo pour Agadir: HTTPSConnectionPool(host='api.open-meteo.com', port=443): Max retries exceeded with url: /v1/forecast?latitude=30.4205162&longitude=-9.5838532&current=temperature_2m%2Crelative_humidity_2m%2Capparent_temperature%2Cis_day%2Cprecipitation%2Crain%2Cshowers%2Csnowfall%2Cweather_code%2Ccloud_cover%2Cpressure_msl%2Csurface_pressure (Caused by NameResolutionError("<urllib3.connection.HTTPSConnection object at 0x7f9c7a2f22a0>: Failed to resolve 'api.open-meteo.com' ([Errno -2] Name or service not known)"))
[2024-12-01T05:06:18.723+0000] {kafka_stream.py:94} ERROR - Erreur lors de la récupération des données d'OpenWeatherMap pour Tanger: HTTPConnectionPool(host='api.openweathermap.org', port=80): Max retries exceeded with url: /data/2.5/weather?q=Tanger%2Cma&appid=8167e2dfee0bd9f28f8eafbd9e355ad3&units=metric (Caused by NameResolutionError("<urllib3.connection.HTTPConnection object at 0x7f9c7a340500>: Failed to resolve 'api.openweathermap.org' ([Errno -2] Name or service not known)"))
[2024-12-01T05:06:18.748+0000] {kafka_stream.py:119} ERROR - Erreur lors de la récupération des données d'Open-Meteo pour Tanger: HTTPSConnectionPool(host='api.open-meteo.com', port=443): Max retries exceeded with url: /v1/forecast?latitude=35.7696302&longitude=-5.8033522&current=temperature_2m%2Crelative_humidity_2m%2Capparent_temperature%2Cis_day%2Cprecipitation%2Crain%2Cshowers%2Csnowfall%2Cweather_code%2Ccloud_cover%2Cpressure_msl%2Csurface_pressure (Caused by NameResolutionError("<urllib3.connection.HTTPSConnection object at 0x7f9c7a3415b0>: Failed to resolve 'api.open-meteo.com' ([Errno -2] Name or service not known)"))
[2024-12-01T05:06:18.760+0000] {kafka_stream.py:94} ERROR - Erreur lors de la récupération des données d'OpenWeatherMap pour Meknès: HTTPConnectionPool(host='api.openweathermap.org', port=80): Max retries exceeded with url: /data/2.5/weather?q=Mekn%C3%A8s%2Cma&appid=8167e2dfee0bd9f28f8eafbd9e355ad3&units=metric (Caused by NameResolutionError("<urllib3.connection.HTTPConnection object at 0x7f9c7a341d60>: Failed to resolve 'api.openweathermap.org' ([Errno -2] Name or service not known)"))
[2024-12-01T05:06:18.771+0000] {kafka_stream.py:119} ERROR - Erreur lors de la récupération des données d'Open-Meteo pour Meknès: HTTPSConnectionPool(host='api.open-meteo.com', port=443): Max retries exceeded with url: /v1/forecast?latitude=33.8984131&longitude=-5.5321582&current=temperature_2m%2Crelative_humidity_2m%2Capparent_temperature%2Cis_day%2Cprecipitation%2Crain%2Cshowers%2Csnowfall%2Cweather_code%2Ccloud_cover%2Cpressure_msl%2Csurface_pressure (Caused by NameResolutionError("<urllib3.connection.HTTPSConnection object at 0x7f9c7a342990>: Failed to resolve 'api.open-meteo.com' ([Errno -2] Name or service not known)"))
[2024-12-01T05:06:18.797+0000] {kafka_stream.py:94} ERROR - Erreur lors de la récupération des données d'OpenWeatherMap pour Oujda: HTTPConnectionPool(host='api.openweathermap.org', port=80): Max retries exceeded with url: /data/2.5/weather?q=Oujda%2Cma&appid=8167e2dfee0bd9f28f8eafbd9e355ad3&units=metric (Caused by NameResolutionError("<urllib3.connection.HTTPConnection object at 0x7f9c7a2f24e0>: Failed to resolve 'api.openweathermap.org' ([Errno -2] Name or service not known)"))
[2024-12-01T05:06:18.821+0000] {kafka_stream.py:119} ERROR - Erreur lors de la récupération des données d'Open-Meteo pour Oujda: HTTPSConnectionPool(host='api.open-meteo.com', port=443): Max retries exceeded with url: /v1/forecast?latitude=34.677874&longitude=-1.929306&current=temperature_2m%2Crelative_humidity_2m%2Capparent_temperature%2Cis_day%2Cprecipitation%2Crain%2Cshowers%2Csnowfall%2Cweather_code%2Ccloud_cover%2Cpressure_msl%2Csurface_pressure (Caused by NameResolutionError("<urllib3.connection.HTTPSConnection object at 0x7f9c7a2f3c20>: Failed to resolve 'api.open-meteo.com' ([Errno -2] Name or service not known)"))
[2024-12-01T05:06:18.839+0000] {kafka_stream.py:94} ERROR - Erreur lors de la récupération des données d'OpenWeatherMap pour Kenitra: HTTPConnectionPool(host='api.openweathermap.org', port=80): Max retries exceeded with url: /data/2.5/weather?q=Kenitra%2Cma&appid=8167e2dfee0bd9f28f8eafbd9e355ad3&units=metric (Caused by NameResolutionError("<urllib3.connection.HTTPConnection object at 0x7f9c7a341280>: Failed to resolve 'api.openweathermap.org' ([Errno -2] Name or service not known)"))
[2024-12-01T05:06:18.852+0000] {kafka_stream.py:119} ERROR - Erreur lors de la récupération des données d'Open-Meteo pour Kenitra: HTTPSConnectionPool(host='api.open-meteo.com', port=443): Max retries exceeded with url: /v1/forecast?latitude=34.26457&longitude=-6.570169&current=temperature_2m%2Crelative_humidity_2m%2Capparent_temperature%2Cis_day%2Cprecipitation%2Crain%2Cshowers%2Csnowfall%2Cweather_code%2Ccloud_cover%2Cpressure_msl%2Csurface_pressure (Caused by NameResolutionError("<urllib3.connection.HTTPSConnection object at 0x7f9c7a3417c0>: Failed to resolve 'api.open-meteo.com' ([Errno -2] Name or service not known)"))
[2024-12-01T05:06:18.865+0000] {kafka_stream.py:94} ERROR - Erreur lors de la récupération des données d'OpenWeatherMap pour Tetouan: HTTPConnectionPool(host='api.openweathermap.org', port=80): Max retries exceeded with url: /data/2.5/weather?q=Tetouan%2Cma&appid=8167e2dfee0bd9f28f8eafbd9e355ad3&units=metric (Caused by NameResolutionError("<urllib3.connection.HTTPConnection object at 0x7f9c7a343200>: Failed to resolve 'api.openweathermap.org' ([Errno -2] Name or service not known)"))
[2024-12-01T05:06:18.874+0000] {kafka_stream.py:119} ERROR - Erreur lors de la récupération des données d'Open-Meteo pour Tetouan: HTTPSConnectionPool(host='api.open-meteo.com', port=443): Max retries exceeded with url: /v1/forecast?latitude=35.570175&longitude=-5.3742776&current=temperature_2m%2Crelative_humidity_2m%2Capparent_temperature%2Cis_day%2Cprecipitation%2Crain%2Cshowers%2Csnowfall%2Cweather_code%2Ccloud_cover%2Cpressure_msl%2Csurface_pressure (Caused by NameResolutionError("<urllib3.connection.HTTPSConnection object at 0x7f9c7a343b30>: Failed to resolve 'api.open-meteo.com' ([Errno -2] Name or service not known)"))
[2024-12-01T05:06:18.882+0000] {kafka_stream.py:94} ERROR - Erreur lors de la récupération des données d'OpenWeatherMap pour El Jadida: HTTPConnectionPool(host='api.openweathermap.org', port=80): Max retries exceeded with url: /data/2.5/weather?q=El+Jadida%2Cma&appid=8167e2dfee0bd9f28f8eafbd9e355ad3&units=metric (Caused by NameResolutionError("<urllib3.connection.HTTPConnection object at 0x7f9c7a2f25d0>: Failed to resolve 'api.openweathermap.org' ([Errno -2] Name or service not known)"))
[2024-12-01T05:06:18.892+0000] {kafka_stream.py:119} ERROR - Erreur lors de la récupération des données d'Open-Meteo pour El Jadida: HTTPSConnectionPool(host='api.open-meteo.com', port=443): Max retries exceeded with url: /v1/forecast?latitude=33.22932285&longitude=-8.499356736652636&current=temperature_2m%2Crelative_humidity_2m%2Capparent_temperature%2Cis_day%2Cprecipitation%2Crain%2Cshowers%2Csnowfall%2Cweather_code%2Ccloud_cover%2Cpressure_msl%2Csurface_pressure (Caused by NameResolutionError("<urllib3.connection.HTTPSConnection object at 0x7f9c7a343230>: Failed to resolve 'api.open-meteo.com' ([Errno -2] Name or service not known)"))
[2024-12-01T05:06:18.905+0000] {kafka_stream.py:94} ERROR - Erreur lors de la récupération des données d'OpenWeatherMap pour Safi: HTTPConnectionPool(host='api.openweathermap.org', port=80): Max retries exceeded with url: /data/2.5/weather?q=Safi%2Cma&appid=8167e2dfee0bd9f28f8eafbd9e355ad3&units=metric (Caused by NameResolutionError("<urllib3.connection.HTTPConnection object at 0x7f9c7a340200>: Failed to resolve 'api.openweathermap.org' ([Errno -2] Name or service not known)"))
[2024-12-01T05:06:18.932+0000] {kafka_stream.py:119} ERROR - Erreur lors de la récupération des données d'Open-Meteo pour Safi: HTTPSConnectionPool(host='api.open-meteo.com', port=443): Max retries exceeded with url: /v1/forecast?latitude=32.299424&longitude=-9.239533&current=temperature_2m%2Crelative_humidity_2m%2Capparent_temperature%2Cis_day%2Cprecipitation%2Crain%2Cshowers%2Csnowfall%2Cweather_code%2Ccloud_cover%2Cpressure_msl%2Csurface_pressure (Caused by NameResolutionError("<urllib3.connection.HTTPSConnection object at 0x7f9c7a341e50>: Failed to resolve 'api.open-meteo.com' ([Errno -2] Name or service not known)"))
[2024-12-01T05:06:18.942+0000] {kafka_stream.py:94} ERROR - Erreur lors de la récupération des données d'OpenWeatherMap pour Beni Mellal: HTTPConnectionPool(host='api.openweathermap.org', port=80): Max retries exceeded with url: /data/2.5/weather?q=Beni+Mellal%2Cma&appid=8167e2dfee0bd9f28f8eafbd9e355ad3&units=metric (Caused by NameResolutionError("<urllib3.connection.HTTPConnection object at 0x7f9c7a3541d0>: Failed to resolve 'api.openweathermap.org' ([Errno -2] Name or service not known)"))
[2024-12-01T05:06:18.951+0000] {kafka_stream.py:119} ERROR - Erreur lors de la récupération des données d'Open-Meteo pour Beni Mellal: HTTPSConnectionPool(host='api.open-meteo.com', port=443): Max retries exceeded with url: /v1/forecast?latitude=32.334193&longitude=-6.353335&current=temperature_2m%2Crelative_humidity_2m%2Capparent_temperature%2Cis_day%2Cprecipitation%2Crain%2Cshowers%2Csnowfall%2Cweather_code%2Ccloud_cover%2Cpressure_msl%2Csurface_pressure (Caused by NameResolutionError("<urllib3.connection.HTTPSConnection object at 0x7f9c7a354b30>: Failed to resolve 'api.open-meteo.com' ([Errno -2] Name or service not known)"))
[2024-12-01T05:06:18.963+0000] {kafka_stream.py:94} ERROR - Erreur lors de la récupération des données d'OpenWeatherMap pour Nador: HTTPConnectionPool(host='api.openweathermap.org', port=80): Max retries exceeded with url: /data/2.5/weather?q=Nador%2Cma&appid=8167e2dfee0bd9f28f8eafbd9e355ad3&units=metric (Caused by NameResolutionError("<urllib3.connection.HTTPConnection object at 0x7f9c7a3415b0>: Failed to resolve 'api.openweathermap.org' ([Errno -2] Name or service not known)"))
[2024-12-01T05:06:18.973+0000] {kafka_stream.py:119} ERROR - Erreur lors de la récupération des données d'Open-Meteo pour Nador: HTTPSConnectionPool(host='api.open-meteo.com', port=443): Max retries exceeded with url: /v1/forecast?latitude=35.1739922&longitude=-2.9281198&current=temperature_2m%2Crelative_humidity_2m%2Capparent_temperature%2Cis_day%2Cprecipitation%2Crain%2Cshowers%2Csnowfall%2Cweather_code%2Ccloud_cover%2Cpressure_msl%2Csurface_pressure (Caused by NameResolutionError("<urllib3.connection.HTTPSConnection object at 0x7f9c7a342d20>: Failed to resolve 'api.open-meteo.com' ([Errno -2] Name or service not known)"))
[2024-12-01T05:06:18.986+0000] {kafka_stream.py:94} ERROR - Erreur lors de la récupération des données d'OpenWeatherMap pour Taza: HTTPConnectionPool(host='api.openweathermap.org', port=80): Max retries exceeded with url: /data/2.5/weather?q=Taza%2Cma&appid=8167e2dfee0bd9f28f8eafbd9e355ad3&units=metric (Caused by NameResolutionError("<urllib3.connection.HTTPConnection object at 0x7f9c7a2f2840>: Failed to resolve 'api.openweathermap.org' ([Errno -2] Name or service not known)"))
[2024-12-01T05:06:18.997+0000] {kafka_stream.py:119} ERROR - Erreur lors de la récupération des données d'Open-Meteo pour Taza: HTTPSConnectionPool(host='api.open-meteo.com', port=443): Max retries exceeded with url: /v1/forecast?latitude=34.230155&longitude=-4.010104&current=temperature_2m%2Crelative_humidity_2m%2Capparent_temperature%2Cis_day%2Cprecipitation%2Crain%2Cshowers%2Csnowfall%2Cweather_code%2Ccloud_cover%2Cpressure_msl%2Csurface_pressure (Caused by NameResolutionError("<urllib3.connection.HTTPSConnection object at 0x7f9c7a2f3680>: Failed to resolve 'api.open-meteo.com' ([Errno -2] Name or service not known)"))
[2024-12-01T05:06:19.009+0000] {kafka_stream.py:94} ERROR - Erreur lors de la récupération des données d'OpenWeatherMap pour Essaouira: HTTPConnectionPool(host='api.openweathermap.org', port=80): Max retries exceeded with url: /data/2.5/weather?q=Essaouira%2Cma&appid=8167e2dfee0bd9f28f8eafbd9e355ad3&units=metric (Caused by NameResolutionError("<urllib3.connection.HTTPConnection object at 0x7f9c7a355010>: Failed to resolve 'api.openweathermap.org' ([Errno -2] Name or service not known)"))
[2024-12-01T05:06:19.022+0000] {kafka_stream.py:119} ERROR - Erreur lors de la récupération des données d'Open-Meteo pour Essaouira: HTTPSConnectionPool(host='api.open-meteo.com', port=443): Max retries exceeded with url: /v1/forecast?latitude=31.5118281&longitude=-9.7620903&current=temperature_2m%2Crelative_humidity_2m%2Capparent_temperature%2Cis_day%2Cprecipitation%2Crain%2Cshowers%2Csnowfall%2Cweather_code%2Ccloud_cover%2Cpressure_msl%2Csurface_pressure (Caused by NameResolutionError("<urllib3.connection.HTTPSConnection object at 0x7f9c7a355670>: Failed to resolve 'api.open-meteo.com' ([Errno -2] Name or service not known)"))
[2024-12-01T05:06:19.033+0000] {kafka_stream.py:94} ERROR - Erreur lors de la récupération des données d'OpenWeatherMap pour Khouribga: HTTPConnectionPool(host='api.openweathermap.org', port=80): Max retries exceeded with url: /data/2.5/weather?q=Khouribga%2Cma&appid=8167e2dfee0bd9f28f8eafbd9e355ad3&units=metric (Caused by NameResolutionError("<urllib3.connection.HTTPConnection object at 0x7f9c7a2f2ff0>: Failed to resolve 'api.openweathermap.org' ([Errno -2] Name or service not known)"))
[2024-12-01T05:06:19.043+0000] {kafka_stream.py:119} ERROR - Erreur lors de la récupération des données d'Open-Meteo pour Khouribga: HTTPSConnectionPool(host='api.open-meteo.com', port=443): Max retries exceeded with url: /v1/forecast?latitude=32.8856482&longitude=-6.908798&current=temperature_2m%2Crelative_humidity_2m%2Capparent_temperature%2Cis_day%2Cprecipitation%2Crain%2Cshowers%2Csnowfall%2Cweather_code%2Ccloud_cover%2Cpressure_msl%2Csurface_pressure (Caused by NameResolutionError("<urllib3.connection.HTTPSConnection object at 0x7f9c7a342c00>: Failed to resolve 'api.open-meteo.com' ([Errno -2] Name or service not known)"))
[2024-12-01T05:06:19.060+0000] {kafka_stream.py:94} ERROR - Erreur lors de la récupération des données d'OpenWeatherMap pour Settat: HTTPConnectionPool(host='api.openweathermap.org', port=80): Max retries exceeded with url: /data/2.5/weather?q=Settat%2Cma&appid=8167e2dfee0bd9f28f8eafbd9e355ad3&units=metric (Caused by NameResolutionError("<urllib3.connection.HTTPConnection object at 0x7f9c7a341340>: Failed to resolve 'api.openweathermap.org' ([Errno -2] Name or service not known)"))
[2024-12-01T05:06:19.085+0000] {kafka_stream.py:119} ERROR - Erreur lors de la récupération des données d'Open-Meteo pour Settat: HTTPSConnectionPool(host='api.open-meteo.com', port=443): Max retries exceeded with url: /v1/forecast?latitude=33.002397&longitude=-7.619867&current=temperature_2m%2Crelative_humidity_2m%2Capparent_temperature%2Cis_day%2Cprecipitation%2Crain%2Cshowers%2Csnowfall%2Cweather_code%2Ccloud_cover%2Cpressure_msl%2Csurface_pressure (Caused by NameResolutionError("<urllib3.connection.HTTPSConnection object at 0x7f9c7a354d70>: Failed to resolve 'api.open-meteo.com' ([Errno -2] Name or service not known)"))
[2024-12-01T05:06:19.114+0000] {kafka_stream.py:94} ERROR - Erreur lors de la récupération des données d'OpenWeatherMap pour Larache: HTTPConnectionPool(host='api.openweathermap.org', port=80): Max retries exceeded with url: /data/2.5/weather?q=Larache%2Cma&appid=8167e2dfee0bd9f28f8eafbd9e355ad3&units=metric (Caused by NameResolutionError("<urllib3.connection.HTTPConnection object at 0x7f9c7a356090>: Failed to resolve 'api.openweathermap.org' ([Errno -2] Name or service not known)"))
[2024-12-01T05:06:19.124+0000] {kafka_stream.py:119} ERROR - Erreur lors de la récupération des données d'Open-Meteo pour Larache: HTTPSConnectionPool(host='api.open-meteo.com', port=443): Max retries exceeded with url: /v1/forecast?latitude=35.1952327&longitude=-6.152913&current=temperature_2m%2Crelative_humidity_2m%2Capparent_temperature%2Cis_day%2Cprecipitation%2Crain%2Cshowers%2Csnowfall%2Cweather_code%2Ccloud_cover%2Cpressure_msl%2Csurface_pressure (Caused by NameResolutionError("<urllib3.connection.HTTPSConnection object at 0x7f9c7a356ae0>: Failed to resolve 'api.open-meteo.com' ([Errno -2] Name or service not known)"))
[2024-12-01T05:06:19.143+0000] {kafka_stream.py:94} ERROR - Erreur lors de la récupération des données d'OpenWeatherMap pour Ksar El Kebir: HTTPConnectionPool(host='api.openweathermap.org', port=80): Max retries exceeded with url: /data/2.5/weather?q=Ksar+El+Kebir%2Cma&appid=8167e2dfee0bd9f28f8eafbd9e355ad3&units=metric (Caused by NameResolutionError("<urllib3.connection.HTTPConnection object at 0x7f9c7a340980>: Failed to resolve 'api.openweathermap.org' ([Errno -2] Name or service not known)"))
[2024-12-01T05:06:19.159+0000] {kafka_stream.py:119} ERROR - Erreur lors de la récupération des données d'Open-Meteo pour Ksar El Kebir: HTTPSConnectionPool(host='api.open-meteo.com', port=443): Max retries exceeded with url: /v1/forecast?latitude=34.999218&longitude=-5.898724&current=temperature_2m%2Crelative_humidity_2m%2Capparent_temperature%2Cis_day%2Cprecipitation%2Crain%2Cshowers%2Csnowfall%2Cweather_code%2Ccloud_cover%2Cpressure_msl%2Csurface_pressure (Caused by NameResolutionError("<urllib3.connection.HTTPSConnection object at 0x7f9c7a2f2f30>: Failed to resolve 'api.open-meteo.com' ([Errno -2] Name or service not known)"))
[2024-12-01T05:06:19.170+0000] {kafka_stream.py:94} ERROR - Erreur lors de la récupération des données d'OpenWeatherMap pour Taourirt: HTTPConnectionPool(host='api.openweathermap.org', port=80): Max retries exceeded with url: /data/2.5/weather?q=Taourirt%2Cma&appid=8167e2dfee0bd9f28f8eafbd9e355ad3&units=metric (Caused by NameResolutionError("<urllib3.connection.HTTPConnection object at 0x7f9c7a2f3ce0>: Failed to resolve 'api.openweathermap.org' ([Errno -2] Name or service not known)"))
[2024-12-01T05:06:19.187+0000] {kafka_stream.py:119} ERROR - Erreur lors de la récupération des données d'Open-Meteo pour Taourirt: HTTPSConnectionPool(host='api.open-meteo.com', port=443): Max retries exceeded with url: /v1/forecast?latitude=34.413438&longitude=-2.893825&current=temperature_2m%2Crelative_humidity_2m%2Capparent_temperature%2Cis_day%2Cprecipitation%2Crain%2Cshowers%2Csnowfall%2Cweather_code%2Ccloud_cover%2Cpressure_msl%2Csurface_pressure (Caused by NameResolutionError("<urllib3.connection.HTTPSConnection object at 0x7f9c7a354f50>: Failed to resolve 'api.open-meteo.com' ([Errno -2] Name or service not known)"))
[2024-12-01T05:06:19.196+0000] {kafka_stream.py:94} ERROR - Erreur lors de la récupération des données d'OpenWeatherMap pour Guercif: HTTPConnectionPool(host='api.openweathermap.org', port=80): Max retries exceeded with url: /data/2.5/weather?q=Guercif%2Cma&appid=8167e2dfee0bd9f28f8eafbd9e355ad3&units=metric (Caused by NameResolutionError("<urllib3.connection.HTTPConnection object at 0x7f9c7a356f90>: Failed to resolve 'api.openweathermap.org' ([Errno -2] Name or service not known)"))
[2024-12-01T05:06:19.206+0000] {kafka_stream.py:119} ERROR - Erreur lors de la récupération des données d'Open-Meteo pour Guercif: HTTPSConnectionPool(host='api.open-meteo.com', port=443): Max retries exceeded with url: /v1/forecast?latitude=34.225576&longitude=-3.352345&current=temperature_2m%2Crelative_humidity_2m%2Capparent_temperature%2Cis_day%2Cprecipitation%2Crain%2Cshowers%2Csnowfall%2Cweather_code%2Ccloud_cover%2Cpressure_msl%2Csurface_pressure (Caused by NameResolutionError("<urllib3.connection.HTTPSConnection object at 0x7f9c7a3578f0>: Failed to resolve 'api.open-meteo.com' ([Errno -2] Name or service not known)"))
[2024-12-01T05:06:19.217+0000] {kafka_stream.py:94} ERROR - Erreur lors de la récupération des données d'OpenWeatherMap pour Guelmim: HTTPConnectionPool(host='api.openweathermap.org', port=80): Max retries exceeded with url: /data/2.5/weather?q=Guelmim%2Cma&appid=8167e2dfee0bd9f28f8eafbd9e355ad3&units=metric (Caused by NameResolutionError("<urllib3.connection.HTTPConnection object at 0x7f9c7a2f2450>: Failed to resolve 'api.openweathermap.org' ([Errno -2] Name or service not known)"))
[2024-12-01T05:06:19.230+0000] {kafka_stream.py:119} ERROR - Erreur lors de la récupération des données d'Open-Meteo pour Guelmim: HTTPSConnectionPool(host='api.open-meteo.com', port=443): Max retries exceeded with url: /v1/forecast?latitude=28.9863852&longitude=-10.0574351&current=temperature_2m%2Crelative_humidity_2m%2Capparent_temperature%2Cis_day%2Cprecipitation%2Crain%2Cshowers%2Csnowfall%2Cweather_code%2Ccloud_cover%2Cpressure_msl%2Csurface_pressure (Caused by NameResolutionError("<urllib3.connection.HTTPSConnection object at 0x7f9c7a341f10>: Failed to resolve 'api.open-meteo.com' ([Errno -2] Name or service not known)"))
[2024-12-01T05:06:19.251+0000] {kafka_stream.py:94} ERROR - Erreur lors de la récupération des données d'OpenWeatherMap pour Dakhla: HTTPConnectionPool(host='api.openweathermap.org', port=80): Max retries exceeded with url: /data/2.5/weather?q=Dakhla%2Cma&appid=8167e2dfee0bd9f28f8eafbd9e355ad3&units=metric (Caused by NameResolutionError("<urllib3.connection.HTTPConnection object at 0x7f9c7a343b90>: Failed to resolve 'api.openweathermap.org' ([Errno -2] Name or service not known)"))
[2024-12-01T05:06:19.265+0000] {kafka_stream.py:119} ERROR - Erreur lors de la récupération des données d'Open-Meteo pour Dakhla: HTTPSConnectionPool(host='api.open-meteo.com', port=443): Max retries exceeded with url: /v1/forecast?latitude=23.6940663&longitude=-15.9431274&current=temperature_2m%2Crelative_humidity_2m%2Capparent_temperature%2Cis_day%2Cprecipitation%2Crain%2Cshowers%2Csnowfall%2Cweather_code%2Ccloud_cover%2Cpressure_msl%2Csurface_pressure (Caused by NameResolutionError("<urllib3.connection.HTTPSConnection object at 0x7f9c7a354110>: Failed to resolve 'api.open-meteo.com' ([Errno -2] Name or service not known)"))
[2024-12-01T05:06:19.274+0000] {kafka_stream.py:94} ERROR - Erreur lors de la récupération des données d'OpenWeatherMap pour Laayoune: HTTPConnectionPool(host='api.openweathermap.org', port=80): Max retries exceeded with url: /data/2.5/weather?q=Laayoune%2Cma&appid=8167e2dfee0bd9f28f8eafbd9e355ad3&units=metric (Caused by NameResolutionError("<urllib3.connection.HTTPConnection object at 0x7f9c7a357c50>: Failed to resolve 'api.openweathermap.org' ([Errno -2] Name or service not known)"))
[2024-12-01T05:06:19.283+0000] {kafka_stream.py:119} ERROR - Erreur lors de la récupération des données d'Open-Meteo pour Laayoune: HTTPSConnectionPool(host='api.open-meteo.com', port=443): Max retries exceeded with url: /v1/forecast?latitude=27.154512&longitude=-13.1953921&current=temperature_2m%2Crelative_humidity_2m%2Capparent_temperature%2Cis_day%2Cprecipitation%2Crain%2Cshowers%2Csnowfall%2Cweather_code%2Ccloud_cover%2Cpressure_msl%2Csurface_pressure (Caused by NameResolutionError("<urllib3.connection.HTTPSConnection object at 0x7f9c7a184560>: Failed to resolve 'api.open-meteo.com' ([Errno -2] Name or service not known)"))
[2024-12-01T05:06:19.292+0000] {kafka_stream.py:94} ERROR - Erreur lors de la récupération des données d'OpenWeatherMap pour Ifrane: HTTPConnectionPool(host='api.openweathermap.org', port=80): Max retries exceeded with url: /data/2.5/weather?q=Ifrane%2Cma&appid=8167e2dfee0bd9f28f8eafbd9e355ad3&units=metric (Caused by NameResolutionError("<urllib3.connection.HTTPConnection object at 0x7f9c7a3540b0>: Failed to resolve 'api.openweathermap.org' ([Errno -2] Name or service not known)"))
[2024-12-01T05:06:19.301+0000] {kafka_stream.py:119} ERROR - Erreur lors de la récupération des données d'Open-Meteo pour Ifrane: HTTPSConnectionPool(host='api.open-meteo.com', port=443): Max retries exceeded with url: /v1/forecast?latitude=33.527605&longitude=-5.107408&current=temperature_2m%2Crelative_humidity_2m%2Capparent_temperature%2Cis_day%2Cprecipitation%2Crain%2Cshowers%2Csnowfall%2Cweather_code%2Ccloud_cover%2Cpressure_msl%2Csurface_pressure (Caused by NameResolutionError("<urllib3.connection.HTTPSConnection object at 0x7f9c7a3418e0>: Failed to resolve 'api.open-meteo.com' ([Errno -2] Name or service not known)"))
[2024-12-01T05:06:19.310+0000] {kafka_stream.py:94} ERROR - Erreur lors de la récupération des données d'OpenWeatherMap pour Azrou: HTTPConnectionPool(host='api.openweathermap.org', port=80): Max retries exceeded with url: /data/2.5/weather?q=Azrou%2Cma&appid=8167e2dfee0bd9f28f8eafbd9e355ad3&units=metric (Caused by NameResolutionError("<urllib3.connection.HTTPConnection object at 0x7f9c9e7e7590>: Failed to resolve 'api.openweathermap.org' ([Errno -2] Name or service not known)"))
[2024-12-01T05:06:19.323+0000] {kafka_stream.py:119} ERROR - Erreur lors de la récupération des données d'Open-Meteo pour Azrou: HTTPSConnectionPool(host='api.open-meteo.com', port=443): Max retries exceeded with url: /v1/forecast?latitude=33.436117&longitude=-5.221913&current=temperature_2m%2Crelative_humidity_2m%2Capparent_temperature%2Cis_day%2Cprecipitation%2Crain%2Cshowers%2Csnowfall%2Cweather_code%2Ccloud_cover%2Cpressure_msl%2Csurface_pressure (Caused by NameResolutionError("<urllib3.connection.HTTPSConnection object at 0x7f9c7a343f20>: Failed to resolve 'api.open-meteo.com' ([Errno -2] Name or service not known)"))
[2024-12-01T05:06:19.332+0000] {kafka_stream.py:94} ERROR - Erreur lors de la récupération des données d'OpenWeatherMap pour Errachidia: HTTPConnectionPool(host='api.openweathermap.org', port=80): Max retries exceeded with url: /data/2.5/weather?q=Errachidia%2Cma&appid=8167e2dfee0bd9f28f8eafbd9e355ad3&units=metric (Caused by NameResolutionError("<urllib3.connection.HTTPConnection object at 0x7f9c7a1848f0>: Failed to resolve 'api.openweathermap.org' ([Errno -2] Name or service not known)"))
[2024-12-01T05:06:19.346+0000] {kafka_stream.py:119} ERROR - Erreur lors de la récupération des données d'Open-Meteo pour Errachidia: HTTPSConnectionPool(host='api.open-meteo.com', port=443): Max retries exceeded with url: /v1/forecast?latitude=31.929089&longitude=-4.4340807&current=temperature_2m%2Crelative_humidity_2m%2Capparent_temperature%2Cis_day%2Cprecipitation%2Crain%2Cshowers%2Csnowfall%2Cweather_code%2Ccloud_cover%2Cpressure_msl%2Csurface_pressure (Caused by NameResolutionError("<urllib3.connection.HTTPSConnection object at 0x7f9c7a185280>: Failed to resolve 'api.open-meteo.com' ([Errno -2] Name or service not known)"))
[2024-12-01T05:06:19.354+0000] {kafka_stream.py:94} ERROR - Erreur lors de la récupération des données d'OpenWeatherMap pour Ouarzazate: HTTPConnectionPool(host='api.openweathermap.org', port=80): Max retries exceeded with url: /data/2.5/weather?q=Ouarzazate%2Cma&appid=8167e2dfee0bd9f28f8eafbd9e355ad3&units=metric (Caused by NameResolutionError("<urllib3.connection.HTTPConnection object at 0x7f9c7a2f3a70>: Failed to resolve 'api.openweathermap.org' ([Errno -2] Name or service not known)"))
[2024-12-01T05:06:19.364+0000] {kafka_stream.py:119} ERROR - Erreur lors de la récupération des données d'Open-Meteo pour Ouarzazate: HTTPSConnectionPool(host='api.open-meteo.com', port=443): Max retries exceeded with url: /v1/forecast?latitude=30.920193&longitude=-6.910923&current=temperature_2m%2Crelative_humidity_2m%2Capparent_temperature%2Cis_day%2Cprecipitation%2Crain%2Cshowers%2Csnowfall%2Cweather_code%2Ccloud_cover%2Cpressure_msl%2Csurface_pressure (Caused by NameResolutionError("<urllib3.connection.HTTPSConnection object at 0x7f9c7a3401d0>: Failed to resolve 'api.open-meteo.com' ([Errno -2] Name or service not known)"))
[2024-12-01T05:06:19.378+0000] {kafka_stream.py:94} ERROR - Erreur lors de la récupération des données d'OpenWeatherMap pour Taroudant: HTTPConnectionPool(host='api.openweathermap.org', port=80): Max retries exceeded with url: /data/2.5/weather?q=Taroudant%2Cma&appid=8167e2dfee0bd9f28f8eafbd9e355ad3&units=metric (Caused by NameResolutionError("<urllib3.connection.HTTPConnection object at 0x7f9c7a553bf0>: Failed to resolve 'api.openweathermap.org' ([Errno -2] Name or service not known)"))
[2024-12-01T05:06:19.401+0000] {kafka_stream.py:119} ERROR - Erreur lors de la récupération des données d'Open-Meteo pour Taroudant: HTTPSConnectionPool(host='api.open-meteo.com', port=443): Max retries exceeded with url: /v1/forecast?latitude=30.470651&longitude=-8.877922&current=temperature_2m%2Crelative_humidity_2m%2Capparent_temperature%2Cis_day%2Cprecipitation%2Crain%2Cshowers%2Csnowfall%2Cweather_code%2Ccloud_cover%2Cpressure_msl%2Csurface_pressure (Caused by NameResolutionError("<urllib3.connection.HTTPSConnection object at 0x7f9c7a355f10>: Failed to resolve 'api.open-meteo.com' ([Errno -2] Name or service not known)"))
[2024-12-01T05:06:19.412+0000] {kafka_stream.py:94} ERROR - Erreur lors de la récupération des données d'OpenWeatherMap pour Chefchaouen: HTTPConnectionPool(host='api.openweathermap.org', port=80): Max retries exceeded with url: /data/2.5/weather?q=Chefchaouen%2Cma&appid=8167e2dfee0bd9f28f8eafbd9e355ad3&units=metric (Caused by NameResolutionError("<urllib3.connection.HTTPConnection object at 0x7f9c7a184830>: Failed to resolve 'api.openweathermap.org' ([Errno -2] Name or service not known)"))
[2024-12-01T05:06:19.427+0000] {kafka_stream.py:119} ERROR - Erreur lors de la récupération des données d'Open-Meteo pour Chefchaouen: HTTPSConnectionPool(host='api.open-meteo.com', port=443): Max retries exceeded with url: /v1/forecast?latitude=35.1693724&longitude=-5.275765468193203&current=temperature_2m%2Crelative_humidity_2m%2Capparent_temperature%2Cis_day%2Cprecipitation%2Crain%2Cshowers%2Csnowfall%2Cweather_code%2Ccloud_cover%2Cpressure_msl%2Csurface_pressure (Caused by NameResolutionError("<urllib3.connection.HTTPSConnection object at 0x7f9c7a1857c0>: Failed to resolve 'api.open-meteo.com' ([Errno -2] Name or service not known)"))
[2024-12-01T05:06:19.440+0000] {kafka_stream.py:94} ERROR - Erreur lors de la récupération des données d'OpenWeatherMap pour Berkane: HTTPConnectionPool(host='api.openweathermap.org', port=80): Max retries exceeded with url: /data/2.5/weather?q=Berkane%2Cma&appid=8167e2dfee0bd9f28f8eafbd9e355ad3&units=metric (Caused by NameResolutionError("<urllib3.connection.HTTPConnection object at 0x7f9c7a356f30>: Failed to resolve 'api.openweathermap.org' ([Errno -2] Name or service not known)"))
[2024-12-01T05:06:19.453+0000] {kafka_stream.py:119} ERROR - Erreur lors de la récupération des données d'Open-Meteo pour Berkane: HTTPSConnectionPool(host='api.open-meteo.com', port=443): Max retries exceeded with url: /v1/forecast?latitude=34.9266755&longitude=-2.3294087&current=temperature_2m%2Crelative_humidity_2m%2Capparent_temperature%2Cis_day%2Cprecipitation%2Crain%2Cshowers%2Csnowfall%2Cweather_code%2Ccloud_cover%2Cpressure_msl%2Csurface_pressure (Caused by NameResolutionError("<urllib3.connection.HTTPSConnection object at 0x7f9c7a356e40>: Failed to resolve 'api.open-meteo.com' ([Errno -2] Name or service not known)"))
[2024-12-01T05:06:19.467+0000] {kafka_stream.py:94} ERROR - Erreur lors de la récupération des données d'OpenWeatherMap pour Sidi Kacem: HTTPConnectionPool(host='api.openweathermap.org', port=80): Max retries exceeded with url: /data/2.5/weather?q=Sidi+Kacem%2Cma&appid=8167e2dfee0bd9f28f8eafbd9e355ad3&units=metric (Caused by NameResolutionError("<urllib3.connection.HTTPConnection object at 0x7f9c7a343f20>: Failed to resolve 'api.openweathermap.org' ([Errno -2] Name or service not known)"))
[2024-12-01T05:06:19.478+0000] {kafka_stream.py:119} ERROR - Erreur lors de la récupération des données d'Open-Meteo pour Sidi Kacem: HTTPSConnectionPool(host='api.open-meteo.com', port=443): Max retries exceeded with url: /v1/forecast?latitude=34.226412&longitude=-5.711434&current=temperature_2m%2Crelative_humidity_2m%2Capparent_temperature%2Cis_day%2Cprecipitation%2Crain%2Cshowers%2Csnowfall%2Cweather_code%2Ccloud_cover%2Cpressure_msl%2Csurface_pressure (Caused by NameResolutionError("<urllib3.connection.HTTPSConnection object at 0x7f9c7a2f29c0>: Failed to resolve 'api.open-meteo.com' ([Errno -2] Name or service not known)"))
[2024-12-01T05:06:19.498+0000] {kafka_stream.py:94} ERROR - Erreur lors de la récupération des données d'OpenWeatherMap pour Sidi Slimane: HTTPConnectionPool(host='api.openweathermap.org', port=80): Max retries exceeded with url: /data/2.5/weather?q=Sidi+Slimane%2Cma&appid=8167e2dfee0bd9f28f8eafbd9e355ad3&units=metric (Caused by NameResolutionError("<urllib3.connection.HTTPConnection object at 0x7f9c7a185b20>: Failed to resolve 'api.openweathermap.org' ([Errno -2] Name or service not known)"))
[2024-12-01T05:06:19.516+0000] {kafka_stream.py:119} ERROR - Erreur lors de la récupération des données d'Open-Meteo pour Sidi Slimane: HTTPSConnectionPool(host='api.open-meteo.com', port=443): Max retries exceeded with url: /v1/forecast?latitude=34.259878&longitude=-5.927253&current=temperature_2m%2Crelative_humidity_2m%2Capparent_temperature%2Cis_day%2Cprecipitation%2Crain%2Cshowers%2Csnowfall%2Cweather_code%2Ccloud_cover%2Cpressure_msl%2Csurface_pressure (Caused by NameResolutionError("<urllib3.connection.HTTPSConnection object at 0x7f9c7a186480>: Failed to resolve 'api.open-meteo.com' ([Errno -2] Name or service not known)"))
[2024-12-01T05:06:19.525+0000] {kafka_stream.py:94} ERROR - Erreur lors de la récupération des données d'OpenWeatherMap pour Sidi Ifni: HTTPConnectionPool(host='api.openweathermap.org', port=80): Max retries exceeded with url: /data/2.5/weather?q=Sidi+Ifni%2Cma&appid=8167e2dfee0bd9f28f8eafbd9e355ad3&units=metric (Caused by NameResolutionError("<urllib3.connection.HTTPConnection object at 0x7f9c7a357920>: Failed to resolve 'api.openweathermap.org' ([Errno -2] Name or service not known)"))
[2024-12-01T05:06:19.535+0000] {kafka_stream.py:119} ERROR - Erreur lors de la récupération des données d'Open-Meteo pour Sidi Ifni: HTTPSConnectionPool(host='api.open-meteo.com', port=443): Max retries exceeded with url: /v1/forecast?latitude=29.3791253&longitude=-10.1715632&current=temperature_2m%2Crelative_humidity_2m%2Capparent_temperature%2Cis_day%2Cprecipitation%2Crain%2Cshowers%2Csnowfall%2Cweather_code%2Ccloud_cover%2Cpressure_msl%2Csurface_pressure (Caused by NameResolutionError("<urllib3.connection.HTTPSConnection object at 0x7f9c7a3576b0>: Failed to resolve 'api.open-meteo.com' ([Errno -2] Name or service not known)"))
[2024-12-01T05:06:19.545+0000] {kafka_stream.py:94} ERROR - Erreur lors de la récupération des données d'OpenWeatherMap pour Tiznit: HTTPConnectionPool(host='api.openweathermap.org', port=80): Max retries exceeded with url: /data/2.5/weather?q=Tiznit%2Cma&appid=8167e2dfee0bd9f28f8eafbd9e355ad3&units=metric (Caused by NameResolutionError("<urllib3.connection.HTTPConnection object at 0x7f9c7a356870>: Failed to resolve 'api.openweathermap.org' ([Errno -2] Name or service not known)"))
[2024-12-01T05:06:19.554+0000] {kafka_stream.py:119} ERROR - Erreur lors de la récupération des données d'Open-Meteo pour Tiznit: HTTPSConnectionPool(host='api.open-meteo.com', port=443): Max retries exceeded with url: /v1/forecast?latitude=29.698624&longitude=-9.7312815&current=temperature_2m%2Crelative_humidity_2m%2Capparent_temperature%2Cis_day%2Cprecipitation%2Crain%2Cshowers%2Csnowfall%2Cweather_code%2Ccloud_cover%2Cpressure_msl%2Csurface_pressure (Caused by NameResolutionError("<urllib3.connection.HTTPSConnection object at 0x7f9c7a355430>: Failed to resolve 'api.open-meteo.com' ([Errno -2] Name or service not known)"))
[2024-12-01T05:06:19.566+0000] {kafka_stream.py:94} ERROR - Erreur lors de la récupération des données d'OpenWeatherMap pour Tan-Tan: HTTPConnectionPool(host='api.openweathermap.org', port=80): Max retries exceeded with url: /data/2.5/weather?q=Tan-Tan%2Cma&appid=8167e2dfee0bd9f28f8eafbd9e355ad3&units=metric (Caused by NameResolutionError("<urllib3.connection.HTTPConnection object at 0x7f9c7a3542c0>: Failed to resolve 'api.openweathermap.org' ([Errno -2] Name or service not known)"))
[2024-12-01T05:06:19.587+0000] {kafka_stream.py:119} ERROR - Erreur lors de la récupération des données d'Open-Meteo pour Tan-Tan: HTTPSConnectionPool(host='api.open-meteo.com', port=443): Max retries exceeded with url: /v1/forecast?latitude=28.437553&longitude=-11.098664&current=temperature_2m%2Crelative_humidity_2m%2Capparent_temperature%2Cis_day%2Cprecipitation%2Crain%2Cshowers%2Csnowfall%2Cweather_code%2Ccloud_cover%2Cpressure_msl%2Csurface_pressure (Caused by NameResolutionError("<urllib3.connection.HTTPSConnection object at 0x7f9c7a2f3f20>: Failed to resolve 'api.open-meteo.com' ([Errno -2] Name or service not known)"))
[2024-12-01T05:06:19.589+0000] {python.py:237} INFO - Done. Returned value was: None
[2024-12-01T05:06:19.593+0000] {taskinstance.py:441} INFO - ::group::Post task execution logs
[2024-12-01T05:06:19.626+0000] {taskinstance.py:1206} INFO - Marking task as SUCCESS. dag_id=weather_data_kafka_dag, task_id=stream_data_from_apis, run_id=scheduled__2024-11-30T23:00:00+00:00, execution_date=20241130T230000, start_date=20241201T050616, end_date=20241201T050619
[2024-12-01T05:06:19.744+0000] {local_task_job_runner.py:243} INFO - Task exited with return code 0
[2024-12-01T05:06:19.800+0000] {local_task_job_runner.py:222} INFO - ::endgroup::
