[2024-11-28T19:05:56.302+0000] {local_task_job_runner.py:120} INFO - ::group::Pre task execution logs
[2024-11-28T19:05:56.447+0000] {taskinstance.py:2076} INFO - Dependencies all met for dep_context=non-requeueable deps ti=<TaskInstance: weather_data_kafka_dag.store_openmeteo_data scheduled__2024-11-28T17:00:00+00:00 [queued]>
[2024-11-28T19:05:56.481+0000] {taskinstance.py:2076} INFO - Dependencies all met for dep_context=requeueable deps ti=<TaskInstance: weather_data_kafka_dag.store_openmeteo_data scheduled__2024-11-28T17:00:00+00:00 [queued]>
[2024-11-28T19:05:56.491+0000] {taskinstance.py:2306} INFO - Starting attempt 2 of 4
[2024-11-28T19:05:56.531+0000] {taskinstance.py:2330} INFO - Executing <Task(PythonOperator): store_openmeteo_data> on 2024-11-28 17:00:00+00:00
[2024-11-28T19:05:56.550+0000] {logging_mixin.py:188} WARNING - /home/***/.local/lib/python3.12/site-packages/***/task/task_runner/standard_task_runner.py:62 DeprecationWarning: This process (pid=15968) is multi-threaded, use of fork() may lead to deadlocks in the child.
[2024-11-28T19:05:56.552+0000] {standard_task_runner.py:64} INFO - Started process 15975 to run task
[2024-11-28T19:05:56.551+0000] {standard_task_runner.py:90} INFO - Running: ['***', 'tasks', 'run', 'weather_data_kafka_dag', 'store_openmeteo_data', 'scheduled__2024-11-28T17:00:00+00:00', '--job-id', '176', '--raw', '--subdir', 'DAGS_FOLDER/kafka_stream.py', '--cfg-path', '/tmp/tmpappxtv42']
[2024-11-28T19:05:56.558+0000] {standard_task_runner.py:91} INFO - Job 176: Subtask store_openmeteo_data
[2024-11-28T19:05:56.635+0000] {task_command.py:426} INFO - Running <TaskInstance: weather_data_kafka_dag.store_openmeteo_data scheduled__2024-11-28T17:00:00+00:00 [running]> on host cc9ad6cea7ef
[2024-11-28T19:05:56.802+0000] {taskinstance.py:2648} INFO - Exporting env vars: AIRFLOW_CTX_DAG_OWNER='admin' AIRFLOW_CTX_DAG_ID='weather_data_kafka_dag' AIRFLOW_CTX_TASK_ID='store_openmeteo_data' AIRFLOW_CTX_EXECUTION_DATE='2024-11-28T17:00:00+00:00' AIRFLOW_CTX_TRY_NUMBER='2' AIRFLOW_CTX_DAG_RUN_ID='scheduled__2024-11-28T17:00:00+00:00'
[2024-11-28T19:05:56.804+0000] {taskinstance.py:430} INFO - ::endgroup::
[2024-11-28T19:05:56.821+0000] {taskinstance.py:441} INFO - ::group::Post task execution logs
[2024-11-28T19:05:56.822+0000] {taskinstance.py:2905} ERROR - Task failed with exception
Traceback (most recent call last):
  File "/home/airflow/.local/lib/python3.12/site-packages/airflow/models/taskinstance.py", line 465, in _execute_task
    result = _execute_callable(context=context, **execute_callable_kwargs)
             ^^^^^^^^^^^^^^^^^^^^^^^^^^^^^^^^^^^^^^^^^^^^^^^^^^^^^^^^^^^^^
  File "/home/airflow/.local/lib/python3.12/site-packages/airflow/models/taskinstance.py", line 432, in _execute_callable
    return execute_callable(context=context, **execute_callable_kwargs)
           ^^^^^^^^^^^^^^^^^^^^^^^^^^^^^^^^^^^^^^^^^^^^^^^^^^^^^^^^^^^^
  File "/home/airflow/.local/lib/python3.12/site-packages/airflow/models/baseoperator.py", line 401, in wrapper
    return func(self, *args, **kwargs)
           ^^^^^^^^^^^^^^^^^^^^^^^^^^^
  File "/home/airflow/.local/lib/python3.12/site-packages/airflow/operators/python.py", line 235, in execute
    return_value = self.execute_callable()
                   ^^^^^^^^^^^^^^^^^^^^^^^
  File "/home/airflow/.local/lib/python3.12/site-packages/airflow/operators/python.py", line 252, in execute_callable
    return self.python_callable(*self.op_args, **self.op_kwargs)
           ^^^^^^^^^^^^^^^^^^^^^^^^^^^^^^^^^^^^^^^^^^^^^^^^^^^^^
  File "/opt/airflow/dags/kafka_stream.py", line 150, in store_openmeteo_data
    read_from_kafka_and_store(KAFKA_TOPIC_OPENMETEO, "openmeteo_data.parquet")
  File "/opt/airflow/dags/kafka_stream.py", line 141, in read_from_kafka_and_store
    logging.error(f"Error reading from Kafka topic {topic_name}: {e}")
                                                                  ^
NameError: name 'e' is not defined
[2024-11-28T19:05:56.839+0000] {taskinstance.py:1206} INFO - Marking task as UP_FOR_RETRY. dag_id=weather_data_kafka_dag, task_id=store_openmeteo_data, run_id=scheduled__2024-11-28T17:00:00+00:00, execution_date=20241128T170000, start_date=20241128T190556, end_date=20241128T190556
[2024-11-28T19:05:56.857+0000] {standard_task_runner.py:110} ERROR - Failed to execute job 176 for task store_openmeteo_data (name 'e' is not defined; 15975)
[2024-11-28T19:05:56.889+0000] {local_task_job_runner.py:243} INFO - Task exited with return code 1
[2024-11-28T19:05:56.910+0000] {taskinstance.py:3503} INFO - 0 downstream tasks scheduled from follow-on schedule check
[2024-11-28T19:05:56.913+0000] {local_task_job_runner.py:222} INFO - ::endgroup::
