[2024-12-03T14:33:16.810+0000] {local_task_job_runner.py:120} INFO - ::group::Pre task execution logs
[2024-12-03T14:33:16.834+0000] {taskinstance.py:2076} INFO - Dependencies all met for dep_context=non-requeueable deps ti=<TaskInstance: weather_data_kafka_dag.run_docker_command manual__2024-12-03T14:27:30.456537+00:00 [queued]>
[2024-12-03T14:33:16.844+0000] {taskinstance.py:2076} INFO - Dependencies all met for dep_context=requeueable deps ti=<TaskInstance: weather_data_kafka_dag.run_docker_command manual__2024-12-03T14:27:30.456537+00:00 [queued]>
[2024-12-03T14:33:16.845+0000] {taskinstance.py:2306} INFO - Starting attempt 2 of 4
[2024-12-03T14:33:16.858+0000] {taskinstance.py:2330} INFO - Executing <Task(BashOperator): run_docker_command> on 2024-12-03 14:27:30.456537+00:00
[2024-12-03T14:33:16.865+0000] {logging_mixin.py:188} WARNING - /home/***/.local/lib/python3.12/site-packages/***/task/task_runner/standard_task_runner.py:62 DeprecationWarning: This process (pid=4322) is multi-threaded, use of fork() may lead to deadlocks in the child.
[2024-12-03T14:33:16.866+0000] {standard_task_runner.py:64} INFO - Started process 4324 to run task
[2024-12-03T14:33:16.865+0000] {standard_task_runner.py:90} INFO - Running: ['***', 'tasks', 'run', 'weather_data_kafka_dag', 'run_docker_command', 'manual__2024-12-03T14:27:30.456537+00:00', '--job-id', '750', '--raw', '--subdir', 'DAGS_FOLDER/kafka_stream.py', '--cfg-path', '/tmp/tmp81olvmzh']
[2024-12-03T14:33:16.867+0000] {standard_task_runner.py:91} INFO - Job 750: Subtask run_docker_command
[2024-12-03T14:33:16.905+0000] {task_command.py:426} INFO - Running <TaskInstance: weather_data_kafka_dag.run_docker_command manual__2024-12-03T14:27:30.456537+00:00 [running]> on host 0f9edd113eb4
[2024-12-03T14:33:16.998+0000] {taskinstance.py:2648} INFO - Exporting env vars: AIRFLOW_CTX_DAG_OWNER='admin' AIRFLOW_CTX_DAG_ID='weather_data_kafka_dag' AIRFLOW_CTX_TASK_ID='run_docker_command' AIRFLOW_CTX_EXECUTION_DATE='2024-12-03T14:27:30.456537+00:00' AIRFLOW_CTX_TRY_NUMBER='2' AIRFLOW_CTX_DAG_RUN_ID='manual__2024-12-03T14:27:30.456537+00:00'
[2024-12-03T14:33:17.000+0000] {taskinstance.py:430} INFO - ::endgroup::
[2024-12-03T14:33:17.014+0000] {subprocess.py:63} INFO - Tmp dir root location: /tmp
[2024-12-03T14:33:17.016+0000] {subprocess.py:75} INFO - Running command: ['/usr/bin/bash', '-c', 'docker exec -it spark-master spark-submit --packages com.datastax.spark:spark-cassandra-connector_2.12:3.5.1 --py-files /dependencies.zip /spark_stream.py']
[2024-12-03T14:33:17.025+0000] {subprocess.py:86} INFO - Output:
[2024-12-03T14:33:17.046+0000] {subprocess.py:93} INFO - the input device is not a TTY
[2024-12-03T14:33:17.047+0000] {subprocess.py:97} INFO - Command exited with return code 1
[2024-12-03T14:33:17.048+0000] {taskinstance.py:441} INFO - ::group::Post task execution logs
[2024-12-03T14:33:17.056+0000] {taskinstance.py:2905} ERROR - Task failed with exception
Traceback (most recent call last):
  File "/home/airflow/.local/lib/python3.12/site-packages/airflow/models/taskinstance.py", line 465, in _execute_task
    result = _execute_callable(context=context, **execute_callable_kwargs)
             ^^^^^^^^^^^^^^^^^^^^^^^^^^^^^^^^^^^^^^^^^^^^^^^^^^^^^^^^^^^^^
  File "/home/airflow/.local/lib/python3.12/site-packages/airflow/models/taskinstance.py", line 432, in _execute_callable
    return execute_callable(context=context, **execute_callable_kwargs)
           ^^^^^^^^^^^^^^^^^^^^^^^^^^^^^^^^^^^^^^^^^^^^^^^^^^^^^^^^^^^^
  File "/home/airflow/.local/lib/python3.12/site-packages/airflow/models/baseoperator.py", line 401, in wrapper
    return func(self, *args, **kwargs)
           ^^^^^^^^^^^^^^^^^^^^^^^^^^^
  File "/home/airflow/.local/lib/python3.12/site-packages/airflow/operators/bash.py", line 243, in execute
    raise AirflowException(
airflow.exceptions.AirflowException: Bash command failed. The command returned a non-zero exit code 1.
[2024-12-03T14:33:17.060+0000] {taskinstance.py:1206} INFO - Marking task as UP_FOR_RETRY. dag_id=weather_data_kafka_dag, task_id=run_docker_command, run_id=manual__2024-12-03T14:27:30.456537+00:00, execution_date=20241203T142730, start_date=20241203T143316, end_date=20241203T143317
[2024-12-03T14:33:17.078+0000] {standard_task_runner.py:110} ERROR - Failed to execute job 750 for task run_docker_command (Bash command failed. The command returned a non-zero exit code 1.; 4324)
[2024-12-03T14:33:17.120+0000] {local_task_job_runner.py:243} INFO - Task exited with return code 1
[2024-12-03T14:33:17.133+0000] {taskinstance.py:3503} INFO - 0 downstream tasks scheduled from follow-on schedule check
[2024-12-03T14:33:17.136+0000] {local_task_job_runner.py:222} INFO - ::endgroup::
