[2024-11-29T02:14:40.148+0000] {local_task_job_runner.py:120} INFO - ::group::Pre task execution logs
[2024-11-29T02:14:40.299+0000] {taskinstance.py:2076} INFO - Dependencies all met for dep_context=non-requeueable deps ti=<TaskInstance: weather_data_kafka_dag.stream_data_from_apis scheduled__2024-11-29T01:00:00+00:00 [queued]>
[2024-11-29T02:14:40.328+0000] {taskinstance.py:2076} INFO - Dependencies all met for dep_context=requeueable deps ti=<TaskInstance: weather_data_kafka_dag.stream_data_from_apis scheduled__2024-11-29T01:00:00+00:00 [queued]>
[2024-11-29T02:14:40.330+0000] {taskinstance.py:2306} INFO - Starting attempt 1 of 4
[2024-11-29T02:14:40.420+0000] {taskinstance.py:2330} INFO - Executing <Task(PythonOperator): stream_data_from_apis> on 2024-11-29 01:00:00+00:00
[2024-11-29T02:14:40.498+0000] {standard_task_runner.py:90} INFO - Running: ['***', 'tasks', 'run', 'weather_data_kafka_dag', 'stream_data_from_apis', 'scheduled__2024-11-29T01:00:00+00:00', '--job-id', '38', '--raw', '--subdir', 'DAGS_FOLDER/kafka_stream.py', '--cfg-path', '/tmp/tmp8hvj3eu1']
[2024-11-29T02:14:40.535+0000] {logging_mixin.py:188} WARNING - /home/***/.local/lib/python3.12/site-packages/***/task/task_runner/standard_task_runner.py:62 DeprecationWarning: This process (pid=1536) is multi-threaded, use of fork() may lead to deadlocks in the child.
[2024-11-29T02:14:40.539+0000] {standard_task_runner.py:64} INFO - Started process 1550 to run task
[2024-11-29T02:14:40.543+0000] {standard_task_runner.py:91} INFO - Job 38: Subtask stream_data_from_apis
[2024-11-29T02:14:41.170+0000] {task_command.py:426} INFO - Running <TaskInstance: weather_data_kafka_dag.stream_data_from_apis scheduled__2024-11-29T01:00:00+00:00 [running]> on host 8885fe629c2f
[2024-11-29T02:14:41.907+0000] {taskinstance.py:2648} INFO - Exporting env vars: AIRFLOW_CTX_DAG_OWNER='admin' AIRFLOW_CTX_DAG_ID='weather_data_kafka_dag' AIRFLOW_CTX_TASK_ID='stream_data_from_apis' AIRFLOW_CTX_EXECUTION_DATE='2024-11-29T01:00:00+00:00' AIRFLOW_CTX_TRY_NUMBER='1' AIRFLOW_CTX_DAG_RUN_ID='scheduled__2024-11-29T01:00:00+00:00'
[2024-11-29T02:14:41.911+0000] {taskinstance.py:430} INFO - ::endgroup::
[2024-11-29T02:14:42.035+0000] {conn.py:362} INFO - <BrokerConnection node_id=bootstrap-0 host=broker:9092 <connecting> [IPv4 ('172.23.0.9', 9092)]>: connecting to broker:9092 [('172.23.0.9', 9092) IPv4]
[2024-11-29T02:14:42.038+0000] {conn.py:957} INFO - Probing node bootstrap-0 broker version
[2024-11-29T02:14:42.044+0000] {conn.py:393} INFO - <BrokerConnection node_id=bootstrap-0 host=broker:9092 <connecting> [IPv4 ('172.23.0.9', 9092)]>: Connection complete.
[2024-11-29T02:14:42.154+0000] {conn.py:1019} INFO - Broker version identified as 2.6.0
[2024-11-29T02:14:42.155+0000] {conn.py:1020} INFO - Set configuration api_version=(2, 6, 0) to skip auto check_version requests on startup
[2024-11-29T02:14:42.189+0000] {kafka_stream.py:52} ERROR - Erreur lors de la récupération des données d'OpenWeatherMap: HTTPConnectionPool(host='api.openweathermap.org', port=80): Max retries exceeded with url: /data/2.5/weather?q=Paris%2Cfr&appid=9a9d136898d1ab286f37101b7248c88a (Caused by NameResolutionError("<urllib3.connection.HTTPConnection object at 0x7f23fd7cfc20>: Failed to resolve 'api.openweathermap.org' ([Errno -2] Name or service not known)"))
[2024-11-29T02:14:42.205+0000] {kafka_stream.py:76} ERROR - Erreur lors de la récupération des données d'Open-Meteo: HTTPSConnectionPool(host='api.open-meteo.com', port=443): Max retries exceeded with url: /v1/forecast?latitude=48.8566&longitude=2.3522&hourly=temperature_2m (Caused by NameResolutionError("<urllib3.connection.HTTPSConnection object at 0x7f23fd86b710>: Failed to resolve 'api.open-meteo.com' ([Errno -2] Name or service not known)"))
[2024-11-29T02:14:42.503+0000] {kafka_stream.py:52} ERROR - Erreur lors de la récupération des données d'OpenWeatherMap: HTTPConnectionPool(host='api.openweathermap.org', port=80): Max retries exceeded with url: /data/2.5/weather?q=Paris%2Cfr&appid=9a9d136898d1ab286f37101b7248c88a (Caused by NameResolutionError("<urllib3.connection.HTTPConnection object at 0x7f23fd5fab70>: Failed to resolve 'api.openweathermap.org' ([Errno -2] Name or service not known)"))
[2024-11-29T02:14:42.540+0000] {kafka_stream.py:76} ERROR - Erreur lors de la récupération des données d'Open-Meteo: HTTPSConnectionPool(host='api.open-meteo.com', port=443): Max retries exceeded with url: /v1/forecast?latitude=48.8566&longitude=2.3522&hourly=temperature_2m (Caused by NameResolutionError("<urllib3.connection.HTTPSConnection object at 0x7f23fd5fb440>: Failed to resolve 'api.open-meteo.com' ([Errno -2] Name or service not known)"))
[2024-11-29T02:14:42.837+0000] {kafka_stream.py:52} ERROR - Erreur lors de la récupération des données d'OpenWeatherMap: HTTPConnectionPool(host='api.openweathermap.org', port=80): Max retries exceeded with url: /data/2.5/weather?q=Paris%2Cfr&appid=9a9d136898d1ab286f37101b7248c88a (Caused by NameResolutionError("<urllib3.connection.HTTPConnection object at 0x7f23fd5fbd10>: Failed to resolve 'api.openweathermap.org' ([Errno -2] Name or service not known)"))
[2024-11-29T02:14:42.855+0000] {kafka_stream.py:76} ERROR - Erreur lors de la récupération des données d'Open-Meteo: HTTPSConnectionPool(host='api.open-meteo.com', port=443): Max retries exceeded with url: /v1/forecast?latitude=48.8566&longitude=2.3522&hourly=temperature_2m (Caused by NameResolutionError("<urllib3.connection.HTTPSConnection object at 0x7f23fd6546b0>: Failed to resolve 'api.open-meteo.com' ([Errno -2] Name or service not known)"))
[2024-11-29T02:14:43.224+0000] {kafka_stream.py:52} ERROR - Erreur lors de la récupération des données d'OpenWeatherMap: HTTPConnectionPool(host='api.openweathermap.org', port=80): Max retries exceeded with url: /data/2.5/weather?q=Paris%2Cfr&appid=9a9d136898d1ab286f37101b7248c88a (Caused by NameResolutionError("<urllib3.connection.HTTPConnection object at 0x7f23fd655010>: Failed to resolve 'api.openweathermap.org' ([Errno -2] Name or service not known)"))
[2024-11-29T02:14:43.250+0000] {kafka_stream.py:76} ERROR - Erreur lors de la récupération des données d'Open-Meteo: HTTPSConnectionPool(host='api.open-meteo.com', port=443): Max retries exceeded with url: /v1/forecast?latitude=48.8566&longitude=2.3522&hourly=temperature_2m (Caused by NameResolutionError("<urllib3.connection.HTTPSConnection object at 0x7f23fd5fb320>: Failed to resolve 'api.open-meteo.com' ([Errno -2] Name or service not known)"))
[2024-11-29T02:14:43.614+0000] {kafka_stream.py:52} ERROR - Erreur lors de la récupération des données d'OpenWeatherMap: HTTPConnectionPool(host='api.openweathermap.org', port=80): Max retries exceeded with url: /data/2.5/weather?q=Paris%2Cfr&appid=9a9d136898d1ab286f37101b7248c88a (Caused by NameResolutionError("<urllib3.connection.HTTPConnection object at 0x7f23fd5fa030>: Failed to resolve 'api.openweathermap.org' ([Errno -2] Name or service not known)"))
[2024-11-29T02:14:43.631+0000] {kafka_stream.py:76} ERROR - Erreur lors de la récupération des données d'Open-Meteo: HTTPSConnectionPool(host='api.open-meteo.com', port=443): Max retries exceeded with url: /v1/forecast?latitude=48.8566&longitude=2.3522&hourly=temperature_2m (Caused by NameResolutionError("<urllib3.connection.HTTPSConnection object at 0x7f23fd654440>: Failed to resolve 'api.open-meteo.com' ([Errno -2] Name or service not known)"))
[2024-11-29T15:43:14.707+0000] {client_async.py:956} INFO - Closing idle connection bootstrap-0, last active 48512539 ms ago
[2024-11-29T15:43:14.976+0000] {conn.py:673} INFO - <BrokerConnection node_id=bootstrap-0 host=broker:9092 <connected> [IPv4 ('172.23.0.9', 9092)]>: Closing connection. 
[2024-11-29T15:43:14.742+0000] {python.py:237} INFO - Done. Returned value was: None
[2024-11-29T15:43:15.147+0000] {taskinstance.py:441} INFO - ::group::Post task execution logs
[2024-11-29T15:43:15.153+0000] {conn.py:362} INFO - <BrokerConnection node_id=1 host=broker:9092 <connecting> [IPv4 ('172.23.0.9', 9092)]>: connecting to broker:9092 [('172.23.0.9', 9092) IPv4]
[2024-11-29T15:43:15.431+0000] {conn.py:393} INFO - <BrokerConnection node_id=1 host=broker:9092 <connecting> [IPv4 ('172.23.0.9', 9092)]>: Connection complete.
[2024-11-29T15:43:15.563+0000] {taskinstance.py:1206} INFO - Marking task as SUCCESS. dag_id=weather_data_kafka_dag, task_id=stream_data_from_apis, run_id=scheduled__2024-11-29T01:00:00+00:00, execution_date=20241129T010000, start_date=20241129T021440, end_date=20241129T154315
[2024-11-29T15:43:16.959+0000] {local_task_job_runner.py:243} INFO - Task exited with return code 0
[2024-11-29T15:43:17.050+0000] {taskinstance.py:3503} INFO - 2 downstream tasks scheduled from follow-on schedule check
[2024-11-29T15:43:18.408+0000] {local_task_job_runner.py:222} INFO - ::endgroup::
