[2024-11-29T23:04:08.404+0000] {local_task_job_runner.py:120} INFO - ::group::Pre task execution logs
[2024-11-29T23:04:08.429+0000] {taskinstance.py:2076} INFO - Dependencies all met for dep_context=non-requeueable deps ti=<TaskInstance: weather_data_kafka_dag.store_openmeteo_data scheduled__2024-11-29T22:00:00+00:00 [queued]>
[2024-11-29T23:04:08.436+0000] {taskinstance.py:2076} INFO - Dependencies all met for dep_context=requeueable deps ti=<TaskInstance: weather_data_kafka_dag.store_openmeteo_data scheduled__2024-11-29T22:00:00+00:00 [queued]>
[2024-11-29T23:04:08.437+0000] {taskinstance.py:2306} INFO - Starting attempt 1 of 4
[2024-11-29T23:04:08.450+0000] {taskinstance.py:2330} INFO - Executing <Task(PythonOperator): store_openmeteo_data> on 2024-11-29 22:00:00+00:00
[2024-11-29T23:04:08.457+0000] {standard_task_runner.py:90} INFO - Running: ['***', 'tasks', 'run', 'weather_data_kafka_dag', 'store_openmeteo_data', 'scheduled__2024-11-29T22:00:00+00:00', '--job-id', '342', '--raw', '--subdir', 'DAGS_FOLDER/kafka_stream.py', '--cfg-path', '/tmp/tmppm62zhms']
[2024-11-29T23:04:08.458+0000] {logging_mixin.py:188} WARNING - /home/***/.local/lib/python3.12/site-packages/***/task/task_runner/standard_task_runner.py:62 DeprecationWarning: This process (pid=14428) is multi-threaded, use of fork() may lead to deadlocks in the child.
[2024-11-29T23:04:08.459+0000] {standard_task_runner.py:91} INFO - Job 342: Subtask store_openmeteo_data
[2024-11-29T23:04:08.460+0000] {standard_task_runner.py:64} INFO - Started process 14432 to run task
[2024-11-29T23:04:08.504+0000] {task_command.py:426} INFO - Running <TaskInstance: weather_data_kafka_dag.store_openmeteo_data scheduled__2024-11-29T22:00:00+00:00 [running]> on host 0741a2a1545f
[2024-11-29T23:04:08.593+0000] {taskinstance.py:2648} INFO - Exporting env vars: AIRFLOW_CTX_DAG_OWNER='admin' AIRFLOW_CTX_DAG_ID='weather_data_kafka_dag' AIRFLOW_CTX_TASK_ID='store_openmeteo_data' AIRFLOW_CTX_EXECUTION_DATE='2024-11-29T22:00:00+00:00' AIRFLOW_CTX_TRY_NUMBER='1' AIRFLOW_CTX_DAG_RUN_ID='scheduled__2024-11-29T22:00:00+00:00'
[2024-11-29T23:04:08.594+0000] {taskinstance.py:430} INFO - ::endgroup::
[2024-11-29T23:04:08.605+0000] {taskinstance.py:441} INFO - ::group::Post task execution logs
[2024-11-29T23:04:08.606+0000] {taskinstance.py:2905} ERROR - Task failed with exception
Traceback (most recent call last):
  File "/home/airflow/.local/lib/python3.12/site-packages/airflow/models/taskinstance.py", line 465, in _execute_task
    result = _execute_callable(context=context, **execute_callable_kwargs)
             ^^^^^^^^^^^^^^^^^^^^^^^^^^^^^^^^^^^^^^^^^^^^^^^^^^^^^^^^^^^^^
  File "/home/airflow/.local/lib/python3.12/site-packages/airflow/models/taskinstance.py", line 432, in _execute_callable
    return execute_callable(context=context, **execute_callable_kwargs)
           ^^^^^^^^^^^^^^^^^^^^^^^^^^^^^^^^^^^^^^^^^^^^^^^^^^^^^^^^^^^^
  File "/home/airflow/.local/lib/python3.12/site-packages/airflow/models/baseoperator.py", line 401, in wrapper
    return func(self, *args, **kwargs)
           ^^^^^^^^^^^^^^^^^^^^^^^^^^^
  File "/home/airflow/.local/lib/python3.12/site-packages/airflow/operators/python.py", line 235, in execute
    return_value = self.execute_callable()
                   ^^^^^^^^^^^^^^^^^^^^^^^
  File "/home/airflow/.local/lib/python3.12/site-packages/airflow/operators/python.py", line 252, in execute_callable
    return self.python_callable(*self.op_args, **self.op_kwargs)
           ^^^^^^^^^^^^^^^^^^^^^^^^^^^^^^^^^^^^^^^^^^^^^^^^^^^^^
  File "/opt/airflow/dags/kafka_stream.py", line 150, in store_openmeteo_data
    read_from_kafka_and_store(KAFKA_TOPIC_OPENMETEO, "openmeteo_data.parquet")
  File "/opt/airflow/dags/kafka_stream.py", line 141, in read_from_kafka_and_store
    logging.error(f"Error reading from Kafka topic {topic_name}: {e}")
                                                                  ^
NameError: name 'e' is not defined
[2024-11-29T23:04:08.618+0000] {taskinstance.py:1206} INFO - Marking task as UP_FOR_RETRY. dag_id=weather_data_kafka_dag, task_id=store_openmeteo_data, run_id=scheduled__2024-11-29T22:00:00+00:00, execution_date=20241129T220000, start_date=20241129T230408, end_date=20241129T230408
[2024-11-29T23:04:08.629+0000] {standard_task_runner.py:110} ERROR - Failed to execute job 342 for task store_openmeteo_data (name 'e' is not defined; 14432)
[2024-11-29T23:04:08.673+0000] {local_task_job_runner.py:243} INFO - Task exited with return code 1
[2024-11-29T23:04:08.686+0000] {local_task_job_runner.py:222} INFO - ::endgroup::
