[2024-12-01T21:30:29.162+0000] {local_task_job_runner.py:120} INFO - ::group::Pre task execution logs
[2024-12-01T21:30:29.239+0000] {taskinstance.py:2076} INFO - Dependencies all met for dep_context=non-requeueable deps ti=<TaskInstance: weather_data_kafka_dag.stream_data_from_apis scheduled__2024-12-01T20:00:00+00:00 [queued]>
[2024-12-01T21:30:29.247+0000] {taskinstance.py:2076} INFO - Dependencies all met for dep_context=requeueable deps ti=<TaskInstance: weather_data_kafka_dag.stream_data_from_apis scheduled__2024-12-01T20:00:00+00:00 [queued]>
[2024-12-01T21:30:29.253+0000] {taskinstance.py:2306} INFO - Starting attempt 1 of 4
[2024-12-01T21:30:29.390+0000] {taskinstance.py:2330} INFO - Executing <Task(PythonOperator): stream_data_from_apis> on 2024-12-01 20:00:00+00:00
[2024-12-01T21:30:29.399+0000] {logging_mixin.py:188} WARNING - /home/***/.local/lib/python3.12/site-packages/***/task/task_runner/standard_task_runner.py:62 DeprecationWarning: This process (pid=8664) is multi-threaded, use of fork() may lead to deadlocks in the child.
[2024-12-01T21:30:29.399+0000] {standard_task_runner.py:90} INFO - Running: ['***', 'tasks', 'run', 'weather_data_kafka_dag', 'stream_data_from_apis', 'scheduled__2024-12-01T20:00:00+00:00', '--job-id', '574', '--raw', '--subdir', 'DAGS_FOLDER/kafka_stream.py', '--cfg-path', '/tmp/tmpxs_pnj3h']
[2024-12-01T21:30:29.401+0000] {standard_task_runner.py:64} INFO - Started process 8669 to run task
[2024-12-01T21:30:29.402+0000] {standard_task_runner.py:91} INFO - Job 574: Subtask stream_data_from_apis
[2024-12-01T21:30:29.555+0000] {task_command.py:426} INFO - Running <TaskInstance: weather_data_kafka_dag.stream_data_from_apis scheduled__2024-12-01T20:00:00+00:00 [running]> on host 0741a2a1545f
[2024-12-01T21:30:29.872+0000] {taskinstance.py:2648} INFO - Exporting env vars: AIRFLOW_CTX_DAG_OWNER='admin' AIRFLOW_CTX_DAG_ID='weather_data_kafka_dag' AIRFLOW_CTX_TASK_ID='stream_data_from_apis' AIRFLOW_CTX_EXECUTION_DATE='2024-12-01T20:00:00+00:00' AIRFLOW_CTX_TRY_NUMBER='1' AIRFLOW_CTX_DAG_RUN_ID='scheduled__2024-12-01T20:00:00+00:00'
[2024-12-01T21:30:29.874+0000] {taskinstance.py:430} INFO - ::endgroup::
[2024-12-01T21:30:29.891+0000] {conn.py:362} INFO - <BrokerConnection node_id=bootstrap-0 host=broker:9092 <connecting> [IPv4 ('172.18.0.11', 9092)]>: connecting to broker:9092 [('172.18.0.11', 9092) IPv4]
[2024-12-01T21:30:29.892+0000] {conn.py:957} INFO - Probing node bootstrap-0 broker version
[2024-12-01T21:30:29.893+0000] {conn.py:393} INFO - <BrokerConnection node_id=bootstrap-0 host=broker:9092 <connecting> [IPv4 ('172.18.0.11', 9092)]>: Connection complete.
[2024-12-01T21:30:29.997+0000] {conn.py:1019} INFO - Broker version identified as 2.6.0
[2024-12-01T21:30:29.998+0000] {conn.py:1020} INFO - Set configuration api_version=(2, 6, 0) to skip auto check_version requests on startup
[2024-12-01T21:30:30.015+0000] {kafka_stream.py:94} ERROR - Erreur lors de la récupération des données d'OpenWeatherMap pour Casablanca: HTTPConnectionPool(host='api.openweathermap.org', port=80): Max retries exceeded with url: /data/2.5/weather?q=Casablanca%2Cma&appid=8167e2dfee0bd9f28f8eafbd9e355ad3&units=metric (Caused by NameResolutionError("<urllib3.connection.HTTPConnection object at 0x7ff89a82cb90>: Failed to resolve 'api.openweathermap.org' ([Errno -2] Name or service not known)"))
[2024-12-01T21:30:30.019+0000] {kafka_stream.py:119} ERROR - Erreur lors de la récupération des données d'Open-Meteo pour Casablanca: HTTPSConnectionPool(host='api.open-meteo.com', port=443): Max retries exceeded with url: /v1/forecast?latitude=33.5945144&longitude=-7.6200284&current=temperature_2m%2Crelative_humidity_2m%2Capparent_temperature%2Cis_day%2Cprecipitation%2Crain%2Cshowers%2Csnowfall%2Cweather_code%2Ccloud_cover%2Cpressure_msl%2Csurface_pressure (Caused by NameResolutionError("<urllib3.connection.HTTPSConnection object at 0x7ff89a6ecdd0>: Failed to resolve 'api.open-meteo.com' ([Errno -2] Name or service not known)"))
[2024-12-01T21:30:30.024+0000] {kafka_stream.py:94} ERROR - Erreur lors de la récupération des données d'OpenWeatherMap pour Rabat: HTTPConnectionPool(host='api.openweathermap.org', port=80): Max retries exceeded with url: /data/2.5/weather?q=Rabat%2Cma&appid=8167e2dfee0bd9f28f8eafbd9e355ad3&units=metric (Caused by NameResolutionError("<urllib3.connection.HTTPConnection object at 0x7ff89a6ed1f0>: Failed to resolve 'api.openweathermap.org' ([Errno -2] Name or service not known)"))
[2024-12-01T21:30:30.031+0000] {kafka_stream.py:119} ERROR - Erreur lors de la récupération des données d'Open-Meteo pour Rabat: HTTPSConnectionPool(host='api.open-meteo.com', port=443): Max retries exceeded with url: /v1/forecast?latitude=34.02236&longitude=-6.8340222&current=temperature_2m%2Crelative_humidity_2m%2Capparent_temperature%2Cis_day%2Cprecipitation%2Crain%2Cshowers%2Csnowfall%2Cweather_code%2Ccloud_cover%2Cpressure_msl%2Csurface_pressure (Caused by NameResolutionError("<urllib3.connection.HTTPSConnection object at 0x7ff89a6ed910>: Failed to resolve 'api.open-meteo.com' ([Errno -2] Name or service not known)"))
[2024-12-01T21:30:30.035+0000] {kafka_stream.py:94} ERROR - Erreur lors de la récupération des données d'OpenWeatherMap pour Fès: HTTPConnectionPool(host='api.openweathermap.org', port=80): Max retries exceeded with url: /data/2.5/weather?q=F%C3%A8s%2Cma&appid=8167e2dfee0bd9f28f8eafbd9e355ad3&units=metric (Caused by NameResolutionError("<urllib3.connection.HTTPConnection object at 0x7ff89a6ed9a0>: Failed to resolve 'api.openweathermap.org' ([Errno -2] Name or service not known)"))
[2024-12-01T21:30:30.040+0000] {kafka_stream.py:119} ERROR - Erreur lors de la récupération des données d'Open-Meteo pour Fès: HTTPSConnectionPool(host='api.open-meteo.com', port=443): Max retries exceeded with url: /v1/forecast?latitude=34.0346534&longitude=-5.0161926&current=temperature_2m%2Crelative_humidity_2m%2Capparent_temperature%2Cis_day%2Cprecipitation%2Crain%2Cshowers%2Csnowfall%2Cweather_code%2Ccloud_cover%2Cpressure_msl%2Csurface_pressure (Caused by NameResolutionError("<urllib3.connection.HTTPSConnection object at 0x7ff89a6ee600>: Failed to resolve 'api.open-meteo.com' ([Errno -2] Name or service not known)"))
[2024-12-01T21:30:30.044+0000] {kafka_stream.py:94} ERROR - Erreur lors de la récupération des données d'OpenWeatherMap pour Marrakech: HTTPConnectionPool(host='api.openweathermap.org', port=80): Max retries exceeded with url: /data/2.5/weather?q=Marrakech%2Cma&appid=8167e2dfee0bd9f28f8eafbd9e355ad3&units=metric (Caused by NameResolutionError("<urllib3.connection.HTTPConnection object at 0x7ff89a6eee10>: Failed to resolve 'api.openweathermap.org' ([Errno -2] Name or service not known)"))
[2024-12-01T21:30:30.049+0000] {kafka_stream.py:119} ERROR - Erreur lors de la récupération des données d'Open-Meteo pour Marrakech: HTTPSConnectionPool(host='api.open-meteo.com', port=443): Max retries exceeded with url: /v1/forecast?latitude=31.6258257&longitude=-7.9891608&current=temperature_2m%2Crelative_humidity_2m%2Capparent_temperature%2Cis_day%2Cprecipitation%2Crain%2Cshowers%2Csnowfall%2Cweather_code%2Ccloud_cover%2Cpressure_msl%2Csurface_pressure (Caused by NameResolutionError("<urllib3.connection.HTTPSConnection object at 0x7ff89a6ef800>: Failed to resolve 'api.open-meteo.com' ([Errno -2] Name or service not known)"))
[2024-12-01T21:30:30.081+0000] {kafka_stream.py:94} ERROR - Erreur lors de la récupération des données d'OpenWeatherMap pour Agadir: HTTPConnectionPool(host='api.openweathermap.org', port=80): Max retries exceeded with url: /data/2.5/weather?q=Agadir%2Cma&appid=8167e2dfee0bd9f28f8eafbd9e355ad3&units=metric (Caused by NameResolutionError("<urllib3.connection.HTTPConnection object at 0x7ff89a6ef3b0>: Failed to resolve 'api.openweathermap.org' ([Errno -2] Name or service not known)"))
[2024-12-01T21:30:30.086+0000] {kafka_stream.py:119} ERROR - Erreur lors de la récupération des données d'Open-Meteo pour Agadir: HTTPSConnectionPool(host='api.open-meteo.com', port=443): Max retries exceeded with url: /v1/forecast?latitude=30.4205162&longitude=-9.5838532&current=temperature_2m%2Crelative_humidity_2m%2Capparent_temperature%2Cis_day%2Cprecipitation%2Crain%2Cshowers%2Csnowfall%2Cweather_code%2Ccloud_cover%2Cpressure_msl%2Csurface_pressure (Caused by NameResolutionError("<urllib3.connection.HTTPSConnection object at 0x7ff89a6eed50>: Failed to resolve 'api.open-meteo.com' ([Errno -2] Name or service not known)"))
[2024-12-01T21:30:30.091+0000] {kafka_stream.py:94} ERROR - Erreur lors de la récupération des données d'OpenWeatherMap pour Tanger: HTTPConnectionPool(host='api.openweathermap.org', port=80): Max retries exceeded with url: /data/2.5/weather?q=Tanger%2Cma&appid=8167e2dfee0bd9f28f8eafbd9e355ad3&units=metric (Caused by NameResolutionError("<urllib3.connection.HTTPConnection object at 0x7ff89a6edaf0>: Failed to resolve 'api.openweathermap.org' ([Errno -2] Name or service not known)"))
[2024-12-01T21:30:30.096+0000] {kafka_stream.py:119} ERROR - Erreur lors de la récupération des données d'Open-Meteo pour Tanger: HTTPSConnectionPool(host='api.open-meteo.com', port=443): Max retries exceeded with url: /v1/forecast?latitude=35.7696302&longitude=-5.8033522&current=temperature_2m%2Crelative_humidity_2m%2Capparent_temperature%2Cis_day%2Cprecipitation%2Crain%2Cshowers%2Csnowfall%2Cweather_code%2Ccloud_cover%2Cpressure_msl%2Csurface_pressure (Caused by NameResolutionError("<urllib3.connection.HTTPSConnection object at 0x7ff89a6ed5e0>: Failed to resolve 'api.open-meteo.com' ([Errno -2] Name or service not known)"))
[2024-12-01T21:30:30.100+0000] {kafka_stream.py:94} ERROR - Erreur lors de la récupération des données d'OpenWeatherMap pour Meknès: HTTPConnectionPool(host='api.openweathermap.org', port=80): Max retries exceeded with url: /data/2.5/weather?q=Mekn%C3%A8s%2Cma&appid=8167e2dfee0bd9f28f8eafbd9e355ad3&units=metric (Caused by NameResolutionError("<urllib3.connection.HTTPConnection object at 0x7ff89a6ed9a0>: Failed to resolve 'api.openweathermap.org' ([Errno -2] Name or service not known)"))
[2024-12-01T21:30:30.107+0000] {kafka_stream.py:119} ERROR - Erreur lors de la récupération des données d'Open-Meteo pour Meknès: HTTPSConnectionPool(host='api.open-meteo.com', port=443): Max retries exceeded with url: /v1/forecast?latitude=33.8984131&longitude=-5.5321582&current=temperature_2m%2Crelative_humidity_2m%2Capparent_temperature%2Cis_day%2Cprecipitation%2Crain%2Cshowers%2Csnowfall%2Cweather_code%2Ccloud_cover%2Cpressure_msl%2Csurface_pressure (Caused by NameResolutionError("<urllib3.connection.HTTPSConnection object at 0x7ff89a70cf50>: Failed to resolve 'api.open-meteo.com' ([Errno -2] Name or service not known)"))
[2024-12-01T21:30:30.112+0000] {kafka_stream.py:94} ERROR - Erreur lors de la récupération des données d'OpenWeatherMap pour Oujda: HTTPConnectionPool(host='api.openweathermap.org', port=80): Max retries exceeded with url: /data/2.5/weather?q=Oujda%2Cma&appid=8167e2dfee0bd9f28f8eafbd9e355ad3&units=metric (Caused by NameResolutionError("<urllib3.connection.HTTPConnection object at 0x7ff89a6eeba0>: Failed to resolve 'api.openweathermap.org' ([Errno -2] Name or service not known)"))
[2024-12-01T21:30:30.116+0000] {kafka_stream.py:119} ERROR - Erreur lors de la récupération des données d'Open-Meteo pour Oujda: HTTPSConnectionPool(host='api.open-meteo.com', port=443): Max retries exceeded with url: /v1/forecast?latitude=34.677874&longitude=-1.929306&current=temperature_2m%2Crelative_humidity_2m%2Capparent_temperature%2Cis_day%2Cprecipitation%2Crain%2Cshowers%2Csnowfall%2Cweather_code%2Ccloud_cover%2Cpressure_msl%2Csurface_pressure (Caused by NameResolutionError("<urllib3.connection.HTTPSConnection object at 0x7ff89a6edeb0>: Failed to resolve 'api.open-meteo.com' ([Errno -2] Name or service not known)"))
[2024-12-01T21:30:30.120+0000] {kafka_stream.py:94} ERROR - Erreur lors de la récupération des données d'OpenWeatherMap pour Kenitra: HTTPConnectionPool(host='api.openweathermap.org', port=80): Max retries exceeded with url: /data/2.5/weather?q=Kenitra%2Cma&appid=8167e2dfee0bd9f28f8eafbd9e355ad3&units=metric (Caused by NameResolutionError("<urllib3.connection.HTTPConnection object at 0x7ff89a6ef140>: Failed to resolve 'api.openweathermap.org' ([Errno -2] Name or service not known)"))
[2024-12-01T21:30:30.124+0000] {kafka_stream.py:119} ERROR - Erreur lors de la récupération des données d'Open-Meteo pour Kenitra: HTTPSConnectionPool(host='api.open-meteo.com', port=443): Max retries exceeded with url: /v1/forecast?latitude=34.26457&longitude=-6.570169&current=temperature_2m%2Crelative_humidity_2m%2Capparent_temperature%2Cis_day%2Cprecipitation%2Crain%2Cshowers%2Csnowfall%2Cweather_code%2Ccloud_cover%2Cpressure_msl%2Csurface_pressure (Caused by NameResolutionError("<urllib3.connection.HTTPSConnection object at 0x7ff89a6ef350>: Failed to resolve 'api.open-meteo.com' ([Errno -2] Name or service not known)"))
[2024-12-01T21:30:30.129+0000] {kafka_stream.py:94} ERROR - Erreur lors de la récupération des données d'OpenWeatherMap pour Tetouan: HTTPConnectionPool(host='api.openweathermap.org', port=80): Max retries exceeded with url: /data/2.5/weather?q=Tetouan%2Cma&appid=8167e2dfee0bd9f28f8eafbd9e355ad3&units=metric (Caused by NameResolutionError("<urllib3.connection.HTTPConnection object at 0x7ff89a70c770>: Failed to resolve 'api.openweathermap.org' ([Errno -2] Name or service not known)"))
[2024-12-01T21:30:30.133+0000] {kafka_stream.py:119} ERROR - Erreur lors de la récupération des données d'Open-Meteo pour Tetouan: HTTPSConnectionPool(host='api.open-meteo.com', port=443): Max retries exceeded with url: /v1/forecast?latitude=35.570175&longitude=-5.3742776&current=temperature_2m%2Crelative_humidity_2m%2Capparent_temperature%2Cis_day%2Cprecipitation%2Crain%2Cshowers%2Csnowfall%2Cweather_code%2Ccloud_cover%2Cpressure_msl%2Csurface_pressure (Caused by NameResolutionError("<urllib3.connection.HTTPSConnection object at 0x7ff89a70d850>: Failed to resolve 'api.open-meteo.com' ([Errno -2] Name or service not known)"))
[2024-12-01T21:30:30.137+0000] {kafka_stream.py:94} ERROR - Erreur lors de la récupération des données d'OpenWeatherMap pour El Jadida: HTTPConnectionPool(host='api.openweathermap.org', port=80): Max retries exceeded with url: /data/2.5/weather?q=El+Jadida%2Cma&appid=8167e2dfee0bd9f28f8eafbd9e355ad3&units=metric (Caused by NameResolutionError("<urllib3.connection.HTTPConnection object at 0x7ff89a6efda0>: Failed to resolve 'api.openweathermap.org' ([Errno -2] Name or service not known)"))
[2024-12-01T21:30:30.141+0000] {kafka_stream.py:119} ERROR - Erreur lors de la récupération des données d'Open-Meteo pour El Jadida: HTTPSConnectionPool(host='api.open-meteo.com', port=443): Max retries exceeded with url: /v1/forecast?latitude=33.22932285&longitude=-8.499356736652636&current=temperature_2m%2Crelative_humidity_2m%2Capparent_temperature%2Cis_day%2Cprecipitation%2Crain%2Cshowers%2Csnowfall%2Cweather_code%2Ccloud_cover%2Cpressure_msl%2Csurface_pressure (Caused by NameResolutionError("<urllib3.connection.HTTPSConnection object at 0x7ff89a6ee300>: Failed to resolve 'api.open-meteo.com' ([Errno -2] Name or service not known)"))
[2024-12-01T21:30:30.144+0000] {kafka_stream.py:94} ERROR - Erreur lors de la récupération des données d'OpenWeatherMap pour Safi: HTTPConnectionPool(host='api.openweathermap.org', port=80): Max retries exceeded with url: /data/2.5/weather?q=Safi%2Cma&appid=8167e2dfee0bd9f28f8eafbd9e355ad3&units=metric (Caused by NameResolutionError("<urllib3.connection.HTTPConnection object at 0x7ff89a6ecb60>: Failed to resolve 'api.openweathermap.org' ([Errno -2] Name or service not known)"))
[2024-12-01T21:30:30.148+0000] {kafka_stream.py:119} ERROR - Erreur lors de la récupération des données d'Open-Meteo pour Safi: HTTPSConnectionPool(host='api.open-meteo.com', port=443): Max retries exceeded with url: /v1/forecast?latitude=32.299424&longitude=-9.239533&current=temperature_2m%2Crelative_humidity_2m%2Capparent_temperature%2Cis_day%2Cprecipitation%2Crain%2Cshowers%2Csnowfall%2Cweather_code%2Ccloud_cover%2Cpressure_msl%2Csurface_pressure (Caused by NameResolutionError("<urllib3.connection.HTTPSConnection object at 0x7ff89a70c1a0>: Failed to resolve 'api.open-meteo.com' ([Errno -2] Name or service not known)"))
[2024-12-01T21:30:30.151+0000] {kafka_stream.py:94} ERROR - Erreur lors de la récupération des données d'OpenWeatherMap pour Beni Mellal: HTTPConnectionPool(host='api.openweathermap.org', port=80): Max retries exceeded with url: /data/2.5/weather?q=Beni+Mellal%2Cma&appid=8167e2dfee0bd9f28f8eafbd9e355ad3&units=metric (Caused by NameResolutionError("<urllib3.connection.HTTPConnection object at 0x7ff89a6ed9a0>: Failed to resolve 'api.openweathermap.org' ([Errno -2] Name or service not known)"))
[2024-12-01T21:30:30.157+0000] {kafka_stream.py:119} ERROR - Erreur lors de la récupération des données d'Open-Meteo pour Beni Mellal: HTTPSConnectionPool(host='api.open-meteo.com', port=443): Max retries exceeded with url: /v1/forecast?latitude=32.334193&longitude=-6.353335&current=temperature_2m%2Crelative_humidity_2m%2Capparent_temperature%2Cis_day%2Cprecipitation%2Crain%2Cshowers%2Csnowfall%2Cweather_code%2Ccloud_cover%2Cpressure_msl%2Csurface_pressure (Caused by NameResolutionError("<urllib3.connection.HTTPSConnection object at 0x7ff89a70d430>: Failed to resolve 'api.open-meteo.com' ([Errno -2] Name or service not known)"))
[2024-12-01T21:30:30.162+0000] {kafka_stream.py:94} ERROR - Erreur lors de la récupération des données d'OpenWeatherMap pour Nador: HTTPConnectionPool(host='api.openweathermap.org', port=80): Max retries exceeded with url: /data/2.5/weather?q=Nador%2Cma&appid=8167e2dfee0bd9f28f8eafbd9e355ad3&units=metric (Caused by NameResolutionError("<urllib3.connection.HTTPConnection object at 0x7ff89a6edb20>: Failed to resolve 'api.openweathermap.org' ([Errno -2] Name or service not known)"))
[2024-12-01T21:30:30.168+0000] {kafka_stream.py:119} ERROR - Erreur lors de la récupération des données d'Open-Meteo pour Nador: HTTPSConnectionPool(host='api.open-meteo.com', port=443): Max retries exceeded with url: /v1/forecast?latitude=35.1739922&longitude=-2.9281198&current=temperature_2m%2Crelative_humidity_2m%2Capparent_temperature%2Cis_day%2Cprecipitation%2Crain%2Cshowers%2Csnowfall%2Cweather_code%2Ccloud_cover%2Cpressure_msl%2Csurface_pressure (Caused by NameResolutionError("<urllib3.connection.HTTPSConnection object at 0x7ff89a6ee030>: Failed to resolve 'api.open-meteo.com' ([Errno -2] Name or service not known)"))
[2024-12-01T21:30:30.172+0000] {kafka_stream.py:94} ERROR - Erreur lors de la récupération des données d'OpenWeatherMap pour Taza: HTTPConnectionPool(host='api.openweathermap.org', port=80): Max retries exceeded with url: /data/2.5/weather?q=Taza%2Cma&appid=8167e2dfee0bd9f28f8eafbd9e355ad3&units=metric (Caused by NameResolutionError("<urllib3.connection.HTTPConnection object at 0x7ff89a6efbf0>: Failed to resolve 'api.openweathermap.org' ([Errno -2] Name or service not known)"))
[2024-12-01T21:30:30.176+0000] {kafka_stream.py:119} ERROR - Erreur lors de la récupération des données d'Open-Meteo pour Taza: HTTPSConnectionPool(host='api.open-meteo.com', port=443): Max retries exceeded with url: /v1/forecast?latitude=34.230155&longitude=-4.010104&current=temperature_2m%2Crelative_humidity_2m%2Capparent_temperature%2Cis_day%2Cprecipitation%2Crain%2Cshowers%2Csnowfall%2Cweather_code%2Ccloud_cover%2Cpressure_msl%2Csurface_pressure (Caused by NameResolutionError("<urllib3.connection.HTTPSConnection object at 0x7ff89a70cda0>: Failed to resolve 'api.open-meteo.com' ([Errno -2] Name or service not known)"))
[2024-12-01T21:30:30.179+0000] {kafka_stream.py:94} ERROR - Erreur lors de la récupération des données d'OpenWeatherMap pour Essaouira: HTTPConnectionPool(host='api.openweathermap.org', port=80): Max retries exceeded with url: /data/2.5/weather?q=Essaouira%2Cma&appid=8167e2dfee0bd9f28f8eafbd9e355ad3&units=metric (Caused by NameResolutionError("<urllib3.connection.HTTPConnection object at 0x7ff89a70c230>: Failed to resolve 'api.openweathermap.org' ([Errno -2] Name or service not known)"))
[2024-12-01T21:30:30.184+0000] {kafka_stream.py:119} ERROR - Erreur lors de la récupération des données d'Open-Meteo pour Essaouira: HTTPSConnectionPool(host='api.open-meteo.com', port=443): Max retries exceeded with url: /v1/forecast?latitude=31.5118281&longitude=-9.7620903&current=temperature_2m%2Crelative_humidity_2m%2Capparent_temperature%2Cis_day%2Cprecipitation%2Crain%2Cshowers%2Csnowfall%2Cweather_code%2Ccloud_cover%2Cpressure_msl%2Csurface_pressure (Caused by NameResolutionError("<urllib3.connection.HTTPSConnection object at 0x7ff89a70dc10>: Failed to resolve 'api.open-meteo.com' ([Errno -2] Name or service not known)"))
[2024-12-01T21:30:30.190+0000] {kafka_stream.py:94} ERROR - Erreur lors de la récupération des données d'OpenWeatherMap pour Khouribga: HTTPConnectionPool(host='api.openweathermap.org', port=80): Max retries exceeded with url: /data/2.5/weather?q=Khouribga%2Cma&appid=8167e2dfee0bd9f28f8eafbd9e355ad3&units=metric (Caused by NameResolutionError("<urllib3.connection.HTTPConnection object at 0x7ff89a8589b0>: Failed to resolve 'api.openweathermap.org' ([Errno -2] Name or service not known)"))
[2024-12-01T21:30:30.195+0000] {kafka_stream.py:119} ERROR - Erreur lors de la récupération des données d'Open-Meteo pour Khouribga: HTTPSConnectionPool(host='api.open-meteo.com', port=443): Max retries exceeded with url: /v1/forecast?latitude=32.8856482&longitude=-6.908798&current=temperature_2m%2Crelative_humidity_2m%2Capparent_temperature%2Cis_day%2Cprecipitation%2Crain%2Cshowers%2Csnowfall%2Cweather_code%2Ccloud_cover%2Cpressure_msl%2Csurface_pressure (Caused by NameResolutionError("<urllib3.connection.HTTPSConnection object at 0x7ff89a6ee990>: Failed to resolve 'api.open-meteo.com' ([Errno -2] Name or service not known)"))
[2024-12-01T21:30:30.199+0000] {kafka_stream.py:94} ERROR - Erreur lors de la récupération des données d'OpenWeatherMap pour Settat: HTTPConnectionPool(host='api.openweathermap.org', port=80): Max retries exceeded with url: /data/2.5/weather?q=Settat%2Cma&appid=8167e2dfee0bd9f28f8eafbd9e355ad3&units=metric (Caused by NameResolutionError("<urllib3.connection.HTTPConnection object at 0x7ff89a6ee2d0>: Failed to resolve 'api.openweathermap.org' ([Errno -2] Name or service not known)"))
[2024-12-01T21:30:30.203+0000] {kafka_stream.py:119} ERROR - Erreur lors de la récupération des données d'Open-Meteo pour Settat: HTTPSConnectionPool(host='api.open-meteo.com', port=443): Max retries exceeded with url: /v1/forecast?latitude=33.002397&longitude=-7.619867&current=temperature_2m%2Crelative_humidity_2m%2Capparent_temperature%2Cis_day%2Cprecipitation%2Crain%2Cshowers%2Csnowfall%2Cweather_code%2Ccloud_cover%2Cpressure_msl%2Csurface_pressure (Caused by NameResolutionError("<urllib3.connection.HTTPSConnection object at 0x7ff89a70ddc0>: Failed to resolve 'api.open-meteo.com' ([Errno -2] Name or service not known)"))
[2024-12-01T21:30:30.207+0000] {kafka_stream.py:94} ERROR - Erreur lors de la récupération des données d'OpenWeatherMap pour Larache: HTTPConnectionPool(host='api.openweathermap.org', port=80): Max retries exceeded with url: /data/2.5/weather?q=Larache%2Cma&appid=8167e2dfee0bd9f28f8eafbd9e355ad3&units=metric (Caused by NameResolutionError("<urllib3.connection.HTTPConnection object at 0x7ff89a70d5b0>: Failed to resolve 'api.openweathermap.org' ([Errno -2] Name or service not known)"))
[2024-12-01T21:30:30.211+0000] {kafka_stream.py:119} ERROR - Erreur lors de la récupération des données d'Open-Meteo pour Larache: HTTPSConnectionPool(host='api.open-meteo.com', port=443): Max retries exceeded with url: /v1/forecast?latitude=35.1952327&longitude=-6.152913&current=temperature_2m%2Crelative_humidity_2m%2Capparent_temperature%2Cis_day%2Cprecipitation%2Crain%2Cshowers%2Csnowfall%2Cweather_code%2Ccloud_cover%2Cpressure_msl%2Csurface_pressure (Caused by NameResolutionError("<urllib3.connection.HTTPSConnection object at 0x7ff89a70d310>: Failed to resolve 'api.open-meteo.com' ([Errno -2] Name or service not known)"))
[2024-12-01T21:30:30.216+0000] {kafka_stream.py:94} ERROR - Erreur lors de la récupération des données d'OpenWeatherMap pour Ksar El Kebir: HTTPConnectionPool(host='api.openweathermap.org', port=80): Max retries exceeded with url: /data/2.5/weather?q=Ksar+El+Kebir%2Cma&appid=8167e2dfee0bd9f28f8eafbd9e355ad3&units=metric (Caused by NameResolutionError("<urllib3.connection.HTTPConnection object at 0x7ff89a6ed430>: Failed to resolve 'api.openweathermap.org' ([Errno -2] Name or service not known)"))
[2024-12-01T21:30:30.220+0000] {kafka_stream.py:119} ERROR - Erreur lors de la récupération des données d'Open-Meteo pour Ksar El Kebir: HTTPSConnectionPool(host='api.open-meteo.com', port=443): Max retries exceeded with url: /v1/forecast?latitude=34.999218&longitude=-5.898724&current=temperature_2m%2Crelative_humidity_2m%2Capparent_temperature%2Cis_day%2Cprecipitation%2Crain%2Cshowers%2Csnowfall%2Cweather_code%2Ccloud_cover%2Cpressure_msl%2Csurface_pressure (Caused by NameResolutionError("<urllib3.connection.HTTPSConnection object at 0x7ff89a6ee870>: Failed to resolve 'api.open-meteo.com' ([Errno -2] Name or service not known)"))
[2024-12-01T21:30:30.224+0000] {kafka_stream.py:94} ERROR - Erreur lors de la récupération des données d'OpenWeatherMap pour Taourirt: HTTPConnectionPool(host='api.openweathermap.org', port=80): Max retries exceeded with url: /data/2.5/weather?q=Taourirt%2Cma&appid=8167e2dfee0bd9f28f8eafbd9e355ad3&units=metric (Caused by NameResolutionError("<urllib3.connection.HTTPConnection object at 0x7ff89a85acc0>: Failed to resolve 'api.openweathermap.org' ([Errno -2] Name or service not known)"))
[2024-12-01T21:30:30.228+0000] {kafka_stream.py:119} ERROR - Erreur lors de la récupération des données d'Open-Meteo pour Taourirt: HTTPSConnectionPool(host='api.open-meteo.com', port=443): Max retries exceeded with url: /v1/forecast?latitude=34.413438&longitude=-2.893825&current=temperature_2m%2Crelative_humidity_2m%2Capparent_temperature%2Cis_day%2Cprecipitation%2Crain%2Cshowers%2Csnowfall%2Cweather_code%2Ccloud_cover%2Cpressure_msl%2Csurface_pressure (Caused by NameResolutionError("<urllib3.connection.HTTPSConnection object at 0x7ff89a70cf80>: Failed to resolve 'api.open-meteo.com' ([Errno -2] Name or service not known)"))
[2024-12-01T21:30:30.232+0000] {kafka_stream.py:94} ERROR - Erreur lors de la récupération des données d'OpenWeatherMap pour Guercif: HTTPConnectionPool(host='api.openweathermap.org', port=80): Max retries exceeded with url: /data/2.5/weather?q=Guercif%2Cma&appid=8167e2dfee0bd9f28f8eafbd9e355ad3&units=metric (Caused by NameResolutionError("<urllib3.connection.HTTPConnection object at 0x7ff89a70c110>: Failed to resolve 'api.openweathermap.org' ([Errno -2] Name or service not known)"))
[2024-12-01T21:30:30.235+0000] {kafka_stream.py:119} ERROR - Erreur lors de la récupération des données d'Open-Meteo pour Guercif: HTTPSConnectionPool(host='api.open-meteo.com', port=443): Max retries exceeded with url: /v1/forecast?latitude=34.225576&longitude=-3.352345&current=temperature_2m%2Crelative_humidity_2m%2Capparent_temperature%2Cis_day%2Cprecipitation%2Crain%2Cshowers%2Csnowfall%2Cweather_code%2Ccloud_cover%2Cpressure_msl%2Csurface_pressure (Caused by NameResolutionError("<urllib3.connection.HTTPSConnection object at 0x7ff89a70e780>: Failed to resolve 'api.open-meteo.com' ([Errno -2] Name or service not known)"))
[2024-12-01T21:30:30.242+0000] {kafka_stream.py:94} ERROR - Erreur lors de la récupération des données d'OpenWeatherMap pour Guelmim: HTTPConnectionPool(host='api.openweathermap.org', port=80): Max retries exceeded with url: /data/2.5/weather?q=Guelmim%2Cma&appid=8167e2dfee0bd9f28f8eafbd9e355ad3&units=metric (Caused by NameResolutionError("<urllib3.connection.HTTPConnection object at 0x7ff89a70ef60>: Failed to resolve 'api.openweathermap.org' ([Errno -2] Name or service not known)"))
[2024-12-01T21:30:30.247+0000] {kafka_stream.py:119} ERROR - Erreur lors de la récupération des données d'Open-Meteo pour Guelmim: HTTPSConnectionPool(host='api.open-meteo.com', port=443): Max retries exceeded with url: /v1/forecast?latitude=28.9863852&longitude=-10.0574351&current=temperature_2m%2Crelative_humidity_2m%2Capparent_temperature%2Cis_day%2Cprecipitation%2Crain%2Cshowers%2Csnowfall%2Cweather_code%2Ccloud_cover%2Cpressure_msl%2Csurface_pressure (Caused by NameResolutionError("<urllib3.connection.HTTPSConnection object at 0x7ff89a6efce0>: Failed to resolve 'api.open-meteo.com' ([Errno -2] Name or service not known)"))
[2024-12-01T21:30:30.251+0000] {kafka_stream.py:94} ERROR - Erreur lors de la récupération des données d'OpenWeatherMap pour Dakhla: HTTPConnectionPool(host='api.openweathermap.org', port=80): Max retries exceeded with url: /data/2.5/weather?q=Dakhla%2Cma&appid=8167e2dfee0bd9f28f8eafbd9e355ad3&units=metric (Caused by NameResolutionError("<urllib3.connection.HTTPConnection object at 0x7ff89a6ed9a0>: Failed to resolve 'api.openweathermap.org' ([Errno -2] Name or service not known)"))
[2024-12-01T21:30:30.255+0000] {kafka_stream.py:119} ERROR - Erreur lors de la récupération des données d'Open-Meteo pour Dakhla: HTTPSConnectionPool(host='api.open-meteo.com', port=443): Max retries exceeded with url: /v1/forecast?latitude=23.6940663&longitude=-15.9431274&current=temperature_2m%2Crelative_humidity_2m%2Capparent_temperature%2Cis_day%2Cprecipitation%2Crain%2Cshowers%2Csnowfall%2Cweather_code%2Ccloud_cover%2Cpressure_msl%2Csurface_pressure (Caused by NameResolutionError("<urllib3.connection.HTTPSConnection object at 0x7ff89a70e810>: Failed to resolve 'api.open-meteo.com' ([Errno -2] Name or service not known)"))
[2024-12-01T21:30:30.259+0000] {kafka_stream.py:94} ERROR - Erreur lors de la récupération des données d'OpenWeatherMap pour Laayoune: HTTPConnectionPool(host='api.openweathermap.org', port=80): Max retries exceeded with url: /data/2.5/weather?q=Laayoune%2Cma&appid=8167e2dfee0bd9f28f8eafbd9e355ad3&units=metric (Caused by NameResolutionError("<urllib3.connection.HTTPConnection object at 0x7ff89a70dcd0>: Failed to resolve 'api.openweathermap.org' ([Errno -2] Name or service not known)"))
[2024-12-01T21:30:30.264+0000] {kafka_stream.py:119} ERROR - Erreur lors de la récupération des données d'Open-Meteo pour Laayoune: HTTPSConnectionPool(host='api.open-meteo.com', port=443): Max retries exceeded with url: /v1/forecast?latitude=27.154512&longitude=-13.1953921&current=temperature_2m%2Crelative_humidity_2m%2Capparent_temperature%2Cis_day%2Cprecipitation%2Crain%2Cshowers%2Csnowfall%2Cweather_code%2Ccloud_cover%2Cpressure_msl%2Csurface_pressure (Caused by NameResolutionError("<urllib3.connection.HTTPSConnection object at 0x7ff89a70e000>: Failed to resolve 'api.open-meteo.com' ([Errno -2] Name or service not known)"))
[2024-12-01T21:30:30.270+0000] {kafka_stream.py:94} ERROR - Erreur lors de la récupération des données d'OpenWeatherMap pour Ifrane: HTTPConnectionPool(host='api.openweathermap.org', port=80): Max retries exceeded with url: /data/2.5/weather?q=Ifrane%2Cma&appid=8167e2dfee0bd9f28f8eafbd9e355ad3&units=metric (Caused by NameResolutionError("<urllib3.connection.HTTPConnection object at 0x7ff89a70f2c0>: Failed to resolve 'api.openweathermap.org' ([Errno -2] Name or service not known)"))
[2024-12-01T21:30:30.275+0000] {kafka_stream.py:119} ERROR - Erreur lors de la récupération des données d'Open-Meteo pour Ifrane: HTTPSConnectionPool(host='api.open-meteo.com', port=443): Max retries exceeded with url: /v1/forecast?latitude=33.527605&longitude=-5.107408&current=temperature_2m%2Crelative_humidity_2m%2Capparent_temperature%2Cis_day%2Cprecipitation%2Crain%2Cshowers%2Csnowfall%2Cweather_code%2Ccloud_cover%2Cpressure_msl%2Csurface_pressure (Caused by NameResolutionError("<urllib3.connection.HTTPSConnection object at 0x7ff89a6ede80>: Failed to resolve 'api.open-meteo.com' ([Errno -2] Name or service not known)"))
[2024-12-01T21:30:30.280+0000] {kafka_stream.py:94} ERROR - Erreur lors de la récupération des données d'OpenWeatherMap pour Azrou: HTTPConnectionPool(host='api.openweathermap.org', port=80): Max retries exceeded with url: /data/2.5/weather?q=Azrou%2Cma&appid=8167e2dfee0bd9f28f8eafbd9e355ad3&units=metric (Caused by NameResolutionError("<urllib3.connection.HTTPConnection object at 0x7ff89a892990>: Failed to resolve 'api.openweathermap.org' ([Errno -2] Name or service not known)"))
[2024-12-01T21:30:30.284+0000] {kafka_stream.py:119} ERROR - Erreur lors de la récupération des données d'Open-Meteo pour Azrou: HTTPSConnectionPool(host='api.open-meteo.com', port=443): Max retries exceeded with url: /v1/forecast?latitude=33.436117&longitude=-5.221913&current=temperature_2m%2Crelative_humidity_2m%2Capparent_temperature%2Cis_day%2Cprecipitation%2Crain%2Cshowers%2Csnowfall%2Cweather_code%2Ccloud_cover%2Cpressure_msl%2Csurface_pressure (Caused by NameResolutionError("<urllib3.connection.HTTPSConnection object at 0x7ff89a70c800>: Failed to resolve 'api.open-meteo.com' ([Errno -2] Name or service not known)"))
[2024-12-01T21:30:30.289+0000] {kafka_stream.py:94} ERROR - Erreur lors de la récupération des données d'OpenWeatherMap pour Errachidia: HTTPConnectionPool(host='api.openweathermap.org', port=80): Max retries exceeded with url: /data/2.5/weather?q=Errachidia%2Cma&appid=8167e2dfee0bd9f28f8eafbd9e355ad3&units=metric (Caused by NameResolutionError("<urllib3.connection.HTTPConnection object at 0x7ff89a70da00>: Failed to resolve 'api.openweathermap.org' ([Errno -2] Name or service not known)"))
[2024-12-01T21:30:30.293+0000] {kafka_stream.py:119} ERROR - Erreur lors de la récupération des données d'Open-Meteo pour Errachidia: HTTPSConnectionPool(host='api.open-meteo.com', port=443): Max retries exceeded with url: /v1/forecast?latitude=31.929089&longitude=-4.4340807&current=temperature_2m%2Crelative_humidity_2m%2Capparent_temperature%2Cis_day%2Cprecipitation%2Crain%2Cshowers%2Csnowfall%2Cweather_code%2Ccloud_cover%2Cpressure_msl%2Csurface_pressure (Caused by NameResolutionError("<urllib3.connection.HTTPSConnection object at 0x7ff89a70daf0>: Failed to resolve 'api.open-meteo.com' ([Errno -2] Name or service not known)"))
[2024-12-01T21:30:30.298+0000] {kafka_stream.py:94} ERROR - Erreur lors de la récupération des données d'OpenWeatherMap pour Ouarzazate: HTTPConnectionPool(host='api.openweathermap.org', port=80): Max retries exceeded with url: /data/2.5/weather?q=Ouarzazate%2Cma&appid=8167e2dfee0bd9f28f8eafbd9e355ad3&units=metric (Caused by NameResolutionError("<urllib3.connection.HTTPConnection object at 0x7ff89a70f620>: Failed to resolve 'api.openweathermap.org' ([Errno -2] Name or service not known)"))
[2024-12-01T21:30:30.303+0000] {kafka_stream.py:119} ERROR - Erreur lors de la récupération des données d'Open-Meteo pour Ouarzazate: HTTPSConnectionPool(host='api.open-meteo.com', port=443): Max retries exceeded with url: /v1/forecast?latitude=30.920193&longitude=-6.910923&current=temperature_2m%2Crelative_humidity_2m%2Capparent_temperature%2Cis_day%2Cprecipitation%2Crain%2Cshowers%2Csnowfall%2Cweather_code%2Ccloud_cover%2Cpressure_msl%2Csurface_pressure (Caused by NameResolutionError("<urllib3.connection.HTTPSConnection object at 0x7ff89a6efce0>: Failed to resolve 'api.open-meteo.com' ([Errno -2] Name or service not known)"))
[2024-12-01T21:30:30.308+0000] {kafka_stream.py:94} ERROR - Erreur lors de la récupération des données d'OpenWeatherMap pour Taroudant: HTTPConnectionPool(host='api.openweathermap.org', port=80): Max retries exceeded with url: /data/2.5/weather?q=Taroudant%2Cma&appid=8167e2dfee0bd9f28f8eafbd9e355ad3&units=metric (Caused by NameResolutionError("<urllib3.connection.HTTPConnection object at 0x7ff89a6ecfb0>: Failed to resolve 'api.openweathermap.org' ([Errno -2] Name or service not known)"))
[2024-12-01T21:30:30.312+0000] {kafka_stream.py:119} ERROR - Erreur lors de la récupération des données d'Open-Meteo pour Taroudant: HTTPSConnectionPool(host='api.open-meteo.com', port=443): Max retries exceeded with url: /v1/forecast?latitude=30.470651&longitude=-8.877922&current=temperature_2m%2Crelative_humidity_2m%2Capparent_temperature%2Cis_day%2Cprecipitation%2Crain%2Cshowers%2Csnowfall%2Cweather_code%2Ccloud_cover%2Cpressure_msl%2Csurface_pressure (Caused by NameResolutionError("<urllib3.connection.HTTPSConnection object at 0x7ff89a70e750>: Failed to resolve 'api.open-meteo.com' ([Errno -2] Name or service not known)"))
[2024-12-01T21:30:30.317+0000] {kafka_stream.py:94} ERROR - Erreur lors de la récupération des données d'OpenWeatherMap pour Chefchaouen: HTTPConnectionPool(host='api.openweathermap.org', port=80): Max retries exceeded with url: /data/2.5/weather?q=Chefchaouen%2Cma&appid=8167e2dfee0bd9f28f8eafbd9e355ad3&units=metric (Caused by NameResolutionError("<urllib3.connection.HTTPConnection object at 0x7ff89a70d550>: Failed to resolve 'api.openweathermap.org' ([Errno -2] Name or service not known)"))
[2024-12-01T21:30:30.322+0000] {kafka_stream.py:119} ERROR - Erreur lors de la récupération des données d'Open-Meteo pour Chefchaouen: HTTPSConnectionPool(host='api.open-meteo.com', port=443): Max retries exceeded with url: /v1/forecast?latitude=35.1693724&longitude=-5.275765468193203&current=temperature_2m%2Crelative_humidity_2m%2Capparent_temperature%2Cis_day%2Cprecipitation%2Crain%2Cshowers%2Csnowfall%2Cweather_code%2Ccloud_cover%2Cpressure_msl%2Csurface_pressure (Caused by NameResolutionError("<urllib3.connection.HTTPSConnection object at 0x7ff89a70f800>: Failed to resolve 'api.open-meteo.com' ([Errno -2] Name or service not known)"))
[2024-12-01T21:30:30.328+0000] {kafka_stream.py:94} ERROR - Erreur lors de la récupération des données d'OpenWeatherMap pour Berkane: HTTPConnectionPool(host='api.openweathermap.org', port=80): Max retries exceeded with url: /data/2.5/weather?q=Berkane%2Cma&appid=8167e2dfee0bd9f28f8eafbd9e355ad3&units=metric (Caused by NameResolutionError("<urllib3.connection.HTTPConnection object at 0x7ff89a70ffe0>: Failed to resolve 'api.openweathermap.org' ([Errno -2] Name or service not known)"))
[2024-12-01T21:30:30.333+0000] {kafka_stream.py:119} ERROR - Erreur lors de la récupération des données d'Open-Meteo pour Berkane: HTTPSConnectionPool(host='api.open-meteo.com', port=443): Max retries exceeded with url: /v1/forecast?latitude=34.9266755&longitude=-2.3294087&current=temperature_2m%2Crelative_humidity_2m%2Capparent_temperature%2Cis_day%2Cprecipitation%2Crain%2Cshowers%2Csnowfall%2Cweather_code%2Ccloud_cover%2Cpressure_msl%2Csurface_pressure (Caused by NameResolutionError("<urllib3.connection.HTTPSConnection object at 0x7ff89a70c890>: Failed to resolve 'api.open-meteo.com' ([Errno -2] Name or service not known)"))
[2024-12-01T21:30:30.337+0000] {kafka_stream.py:94} ERROR - Erreur lors de la récupération des données d'OpenWeatherMap pour Sidi Kacem: HTTPConnectionPool(host='api.openweathermap.org', port=80): Max retries exceeded with url: /data/2.5/weather?q=Sidi+Kacem%2Cma&appid=8167e2dfee0bd9f28f8eafbd9e355ad3&units=metric (Caused by NameResolutionError("<urllib3.connection.HTTPConnection object at 0x7ff89a70d9a0>: Failed to resolve 'api.openweathermap.org' ([Errno -2] Name or service not known)"))
[2024-12-01T21:30:30.342+0000] {kafka_stream.py:119} ERROR - Erreur lors de la récupération des données d'Open-Meteo pour Sidi Kacem: HTTPSConnectionPool(host='api.open-meteo.com', port=443): Max retries exceeded with url: /v1/forecast?latitude=34.226412&longitude=-5.711434&current=temperature_2m%2Crelative_humidity_2m%2Capparent_temperature%2Cis_day%2Cprecipitation%2Crain%2Cshowers%2Csnowfall%2Cweather_code%2Ccloud_cover%2Cpressure_msl%2Csurface_pressure (Caused by NameResolutionError("<urllib3.connection.HTTPSConnection object at 0x7ff89a6eddf0>: Failed to resolve 'api.open-meteo.com' ([Errno -2] Name or service not known)"))
[2024-12-01T21:30:30.346+0000] {kafka_stream.py:94} ERROR - Erreur lors de la récupération des données d'OpenWeatherMap pour Sidi Slimane: HTTPConnectionPool(host='api.openweathermap.org', port=80): Max retries exceeded with url: /data/2.5/weather?q=Sidi+Slimane%2Cma&appid=8167e2dfee0bd9f28f8eafbd9e355ad3&units=metric (Caused by NameResolutionError("<urllib3.connection.HTTPConnection object at 0x7ff89a6eddc0>: Failed to resolve 'api.openweathermap.org' ([Errno -2] Name or service not known)"))
[2024-12-01T21:30:30.350+0000] {kafka_stream.py:119} ERROR - Erreur lors de la récupération des données d'Open-Meteo pour Sidi Slimane: HTTPSConnectionPool(host='api.open-meteo.com', port=443): Max retries exceeded with url: /v1/forecast?latitude=34.259878&longitude=-5.927253&current=temperature_2m%2Crelative_humidity_2m%2Capparent_temperature%2Cis_day%2Cprecipitation%2Crain%2Cshowers%2Csnowfall%2Cweather_code%2Ccloud_cover%2Cpressure_msl%2Csurface_pressure (Caused by NameResolutionError("<urllib3.connection.HTTPSConnection object at 0x7ff89a6f0260>: Failed to resolve 'api.open-meteo.com' ([Errno -2] Name or service not known)"))
[2024-12-01T21:30:30.355+0000] {kafka_stream.py:94} ERROR - Erreur lors de la récupération des données d'OpenWeatherMap pour Sidi Ifni: HTTPConnectionPool(host='api.openweathermap.org', port=80): Max retries exceeded with url: /data/2.5/weather?q=Sidi+Ifni%2Cma&appid=8167e2dfee0bd9f28f8eafbd9e355ad3&units=metric (Caused by NameResolutionError("<urllib3.connection.HTTPConnection object at 0x7ff89a6f0ad0>: Failed to resolve 'api.openweathermap.org' ([Errno -2] Name or service not known)"))
[2024-12-01T21:30:30.360+0000] {kafka_stream.py:119} ERROR - Erreur lors de la récupération des données d'Open-Meteo pour Sidi Ifni: HTTPSConnectionPool(host='api.open-meteo.com', port=443): Max retries exceeded with url: /v1/forecast?latitude=29.3791253&longitude=-10.1715632&current=temperature_2m%2Crelative_humidity_2m%2Capparent_temperature%2Cis_day%2Cprecipitation%2Crain%2Cshowers%2Csnowfall%2Cweather_code%2Ccloud_cover%2Cpressure_msl%2Csurface_pressure (Caused by NameResolutionError("<urllib3.connection.HTTPSConnection object at 0x7ff89a6ec620>: Failed to resolve 'api.open-meteo.com' ([Errno -2] Name or service not known)"))
[2024-12-01T21:30:30.365+0000] {kafka_stream.py:94} ERROR - Erreur lors de la récupération des données d'OpenWeatherMap pour Tiznit: HTTPConnectionPool(host='api.openweathermap.org', port=80): Max retries exceeded with url: /data/2.5/weather?q=Tiznit%2Cma&appid=8167e2dfee0bd9f28f8eafbd9e355ad3&units=metric (Caused by NameResolutionError("<urllib3.connection.HTTPConnection object at 0x7ff89a6ed9a0>: Failed to resolve 'api.openweathermap.org' ([Errno -2] Name or service not known)"))
[2024-12-01T21:30:30.369+0000] {kafka_stream.py:119} ERROR - Erreur lors de la récupération des données d'Open-Meteo pour Tiznit: HTTPSConnectionPool(host='api.open-meteo.com', port=443): Max retries exceeded with url: /v1/forecast?latitude=29.698624&longitude=-9.7312815&current=temperature_2m%2Crelative_humidity_2m%2Capparent_temperature%2Cis_day%2Cprecipitation%2Crain%2Cshowers%2Csnowfall%2Cweather_code%2Ccloud_cover%2Cpressure_msl%2Csurface_pressure (Caused by NameResolutionError("<urllib3.connection.HTTPSConnection object at 0x7ff89a70eae0>: Failed to resolve 'api.open-meteo.com' ([Errno -2] Name or service not known)"))
[2024-12-01T21:30:30.373+0000] {kafka_stream.py:94} ERROR - Erreur lors de la récupération des données d'OpenWeatherMap pour Tan-Tan: HTTPConnectionPool(host='api.openweathermap.org', port=80): Max retries exceeded with url: /data/2.5/weather?q=Tan-Tan%2Cma&appid=8167e2dfee0bd9f28f8eafbd9e355ad3&units=metric (Caused by NameResolutionError("<urllib3.connection.HTTPConnection object at 0x7ff89a70e000>: Failed to resolve 'api.openweathermap.org' ([Errno -2] Name or service not known)"))
[2024-12-01T21:30:30.378+0000] {kafka_stream.py:119} ERROR - Erreur lors de la récupération des données d'Open-Meteo pour Tan-Tan: HTTPSConnectionPool(host='api.open-meteo.com', port=443): Max retries exceeded with url: /v1/forecast?latitude=28.437553&longitude=-11.098664&current=temperature_2m%2Crelative_humidity_2m%2Capparent_temperature%2Cis_day%2Cprecipitation%2Crain%2Cshowers%2Csnowfall%2Cweather_code%2Ccloud_cover%2Cpressure_msl%2Csurface_pressure (Caused by NameResolutionError("<urllib3.connection.HTTPSConnection object at 0x7ff89a6f0d40>: Failed to resolve 'api.open-meteo.com' ([Errno -2] Name or service not known)"))
[2024-12-01T21:30:30.379+0000] {python.py:237} INFO - Done. Returned value was: None
[2024-12-01T21:30:30.380+0000] {taskinstance.py:441} INFO - ::group::Post task execution logs
[2024-12-01T21:30:30.391+0000] {taskinstance.py:1206} INFO - Marking task as SUCCESS. dag_id=weather_data_kafka_dag, task_id=stream_data_from_apis, run_id=scheduled__2024-12-01T20:00:00+00:00, execution_date=20241201T200000, start_date=20241201T213029, end_date=20241201T213030
[2024-12-01T21:30:30.547+0000] {local_task_job_runner.py:243} INFO - Task exited with return code 0
[2024-12-01T21:30:30.580+0000] {taskinstance.py:3503} INFO - 2 downstream tasks scheduled from follow-on schedule check
[2024-12-01T21:30:30.685+0000] {local_task_job_runner.py:222} INFO - ::endgroup::
