[2024-12-03T14:17:56.129+0000] {local_task_job_runner.py:120} INFO - ::group::Pre task execution logs
[2024-12-03T14:17:56.154+0000] {taskinstance.py:2076} INFO - Dependencies all met for dep_context=non-requeueable deps ti=<TaskInstance: weather_data_kafka_dag.run_docker_command manual__2024-12-03T14:17:21.687179+00:00 [queued]>
[2024-12-03T14:17:56.163+0000] {taskinstance.py:2076} INFO - Dependencies all met for dep_context=requeueable deps ti=<TaskInstance: weather_data_kafka_dag.run_docker_command manual__2024-12-03T14:17:21.687179+00:00 [queued]>
[2024-12-03T14:17:56.164+0000] {taskinstance.py:2306} INFO - Starting attempt 1 of 4
[2024-12-03T14:17:56.176+0000] {taskinstance.py:2330} INFO - Executing <Task(BashOperator): run_docker_command> on 2024-12-03 14:17:21.687179+00:00
[2024-12-03T14:17:56.184+0000] {logging_mixin.py:188} WARNING - /home/***/.local/lib/python3.12/site-packages/***/task/task_runner/standard_task_runner.py:62 DeprecationWarning: This process (pid=3581) is multi-threaded, use of fork() may lead to deadlocks in the child.
[2024-12-03T14:17:56.185+0000] {standard_task_runner.py:64} INFO - Started process 3583 to run task
[2024-12-03T14:17:56.184+0000] {standard_task_runner.py:90} INFO - Running: ['***', 'tasks', 'run', 'weather_data_kafka_dag', 'run_docker_command', 'manual__2024-12-03T14:17:21.687179+00:00', '--job-id', '730', '--raw', '--subdir', 'DAGS_FOLDER/kafka_stream.py', '--cfg-path', '/tmp/tmpk5moxyh2']
[2024-12-03T14:17:56.185+0000] {standard_task_runner.py:91} INFO - Job 730: Subtask run_docker_command
[2024-12-03T14:17:56.222+0000] {task_command.py:426} INFO - Running <TaskInstance: weather_data_kafka_dag.run_docker_command manual__2024-12-03T14:17:21.687179+00:00 [running]> on host 0f9edd113eb4
[2024-12-03T14:17:56.292+0000] {taskinstance.py:2648} INFO - Exporting env vars: AIRFLOW_CTX_DAG_OWNER='admin' AIRFLOW_CTX_DAG_ID='weather_data_kafka_dag' AIRFLOW_CTX_TASK_ID='run_docker_command' AIRFLOW_CTX_EXECUTION_DATE='2024-12-03T14:17:21.687179+00:00' AIRFLOW_CTX_TRY_NUMBER='1' AIRFLOW_CTX_DAG_RUN_ID='manual__2024-12-03T14:17:21.687179+00:00'
[2024-12-03T14:17:56.293+0000] {taskinstance.py:430} INFO - ::endgroup::
[2024-12-03T14:17:56.304+0000] {subprocess.py:63} INFO - Tmp dir root location: /tmp
[2024-12-03T14:17:56.305+0000] {subprocess.py:75} INFO - Running command: ['/usr/bin/bash', '-c', '\nset -e\necho "Starting Spark Submit..."\ndocker exec -it spark-master spark-submit     --packages com.datastax.spark:spark-cassandra-connector_2.12:3.5.1     --py-files /dependencies.zip     /spark_stream.py\necho "Spark Submit Completed"']
[2024-12-03T14:17:56.313+0000] {subprocess.py:86} INFO - Output:
[2024-12-03T14:17:56.314+0000] {subprocess.py:93} INFO - Starting Spark Submit...
[2024-12-03T14:17:56.335+0000] {subprocess.py:93} INFO - the input device is not a TTY
[2024-12-03T14:17:56.336+0000] {subprocess.py:97} INFO - Command exited with return code 1
[2024-12-03T14:17:56.337+0000] {taskinstance.py:441} INFO - ::group::Post task execution logs
[2024-12-03T14:17:56.344+0000] {taskinstance.py:2905} ERROR - Task failed with exception
Traceback (most recent call last):
  File "/home/airflow/.local/lib/python3.12/site-packages/airflow/models/taskinstance.py", line 465, in _execute_task
    result = _execute_callable(context=context, **execute_callable_kwargs)
             ^^^^^^^^^^^^^^^^^^^^^^^^^^^^^^^^^^^^^^^^^^^^^^^^^^^^^^^^^^^^^
  File "/home/airflow/.local/lib/python3.12/site-packages/airflow/models/taskinstance.py", line 432, in _execute_callable
    return execute_callable(context=context, **execute_callable_kwargs)
           ^^^^^^^^^^^^^^^^^^^^^^^^^^^^^^^^^^^^^^^^^^^^^^^^^^^^^^^^^^^^
  File "/home/airflow/.local/lib/python3.12/site-packages/airflow/models/baseoperator.py", line 401, in wrapper
    return func(self, *args, **kwargs)
           ^^^^^^^^^^^^^^^^^^^^^^^^^^^
  File "/home/airflow/.local/lib/python3.12/site-packages/airflow/operators/bash.py", line 243, in execute
    raise AirflowException(
airflow.exceptions.AirflowException: Bash command failed. The command returned a non-zero exit code 1.
[2024-12-03T14:17:56.348+0000] {taskinstance.py:1206} INFO - Marking task as UP_FOR_RETRY. dag_id=weather_data_kafka_dag, task_id=run_docker_command, run_id=manual__2024-12-03T14:17:21.687179+00:00, execution_date=20241203T141721, start_date=20241203T141756, end_date=20241203T141756
[2024-12-03T14:17:56.358+0000] {standard_task_runner.py:110} ERROR - Failed to execute job 730 for task run_docker_command (Bash command failed. The command returned a non-zero exit code 1.; 3583)
[2024-12-03T14:17:56.399+0000] {local_task_job_runner.py:243} INFO - Task exited with return code 1
[2024-12-03T14:17:56.419+0000] {taskinstance.py:3503} INFO - 0 downstream tasks scheduled from follow-on schedule check
[2024-12-03T14:17:56.423+0000] {local_task_job_runner.py:222} INFO - ::endgroup::
