[2024-11-30T20:35:32.642+0000] {local_task_job_runner.py:120} INFO - ::group::Pre task execution logs
[2024-11-30T20:35:32.809+0000] {taskinstance.py:2076} INFO - Dependencies all met for dep_context=non-requeueable deps ti=<TaskInstance: weather_data_kafka_dag.store_openmeteo_data scheduled__2024-11-30T16:00:00+00:00 [queued]>
[2024-11-30T20:35:32.845+0000] {taskinstance.py:2076} INFO - Dependencies all met for dep_context=requeueable deps ti=<TaskInstance: weather_data_kafka_dag.store_openmeteo_data scheduled__2024-11-30T16:00:00+00:00 [queued]>
[2024-11-30T20:35:32.852+0000] {taskinstance.py:2306} INFO - Starting attempt 2 of 4
[2024-11-30T20:35:32.990+0000] {taskinstance.py:2330} INFO - Executing <Task(PythonOperator): store_openmeteo_data> on 2024-11-30 16:00:00+00:00
[2024-11-30T20:35:33.026+0000] {logging_mixin.py:188} WARNING - /home/***/.local/lib/python3.12/site-packages/***/task/task_runner/standard_task_runner.py:62 DeprecationWarning: This process (pid=17294) is multi-threaded, use of fork() may lead to deadlocks in the child.
[2024-11-30T20:35:33.028+0000] {standard_task_runner.py:64} INFO - Started process 17315 to run task
[2024-11-30T20:35:33.023+0000] {standard_task_runner.py:90} INFO - Running: ['***', 'tasks', 'run', 'weather_data_kafka_dag', 'store_openmeteo_data', 'scheduled__2024-11-30T16:00:00+00:00', '--job-id', '447', '--raw', '--subdir', 'DAGS_FOLDER/kafka_stream.py', '--cfg-path', '/tmp/tmpb39f7fuy']
[2024-11-30T20:35:33.039+0000] {standard_task_runner.py:91} INFO - Job 447: Subtask store_openmeteo_data
[2024-11-30T20:35:33.421+0000] {task_command.py:426} INFO - Running <TaskInstance: weather_data_kafka_dag.store_openmeteo_data scheduled__2024-11-30T16:00:00+00:00 [running]> on host 0741a2a1545f
[2024-11-30T20:35:33.918+0000] {taskinstance.py:2648} INFO - Exporting env vars: AIRFLOW_CTX_DAG_OWNER='admin' AIRFLOW_CTX_DAG_ID='weather_data_kafka_dag' AIRFLOW_CTX_TASK_ID='store_openmeteo_data' AIRFLOW_CTX_EXECUTION_DATE='2024-11-30T16:00:00+00:00' AIRFLOW_CTX_TRY_NUMBER='2' AIRFLOW_CTX_DAG_RUN_ID='scheduled__2024-11-30T16:00:00+00:00'
[2024-11-30T20:35:33.923+0000] {taskinstance.py:430} INFO - ::endgroup::
[2024-11-30T20:35:33.963+0000] {taskinstance.py:441} INFO - ::group::Post task execution logs
[2024-11-30T20:35:33.965+0000] {taskinstance.py:2905} ERROR - Task failed with exception
Traceback (most recent call last):
  File "/home/airflow/.local/lib/python3.12/site-packages/airflow/models/taskinstance.py", line 465, in _execute_task
    result = _execute_callable(context=context, **execute_callable_kwargs)
             ^^^^^^^^^^^^^^^^^^^^^^^^^^^^^^^^^^^^^^^^^^^^^^^^^^^^^^^^^^^^^
  File "/home/airflow/.local/lib/python3.12/site-packages/airflow/models/taskinstance.py", line 432, in _execute_callable
    return execute_callable(context=context, **execute_callable_kwargs)
           ^^^^^^^^^^^^^^^^^^^^^^^^^^^^^^^^^^^^^^^^^^^^^^^^^^^^^^^^^^^^
  File "/home/airflow/.local/lib/python3.12/site-packages/airflow/models/baseoperator.py", line 401, in wrapper
    return func(self, *args, **kwargs)
           ^^^^^^^^^^^^^^^^^^^^^^^^^^^
  File "/home/airflow/.local/lib/python3.12/site-packages/airflow/operators/python.py", line 235, in execute
    return_value = self.execute_callable()
                   ^^^^^^^^^^^^^^^^^^^^^^^
  File "/home/airflow/.local/lib/python3.12/site-packages/airflow/operators/python.py", line 252, in execute_callable
    return self.python_callable(*self.op_args, **self.op_kwargs)
           ^^^^^^^^^^^^^^^^^^^^^^^^^^^^^^^^^^^^^^^^^^^^^^^^^^^^^
  File "/opt/airflow/dags/kafka_stream.py", line 151, in store_openmeteo_data
    read_from_kafka_and_store(KAFKA_TOPIC_OPENMETEO, "openmeteo_data.parquet")
  File "/opt/airflow/dags/kafka_stream.py", line 142, in read_from_kafka_and_store
    logging.error(f"Error reading from Kafka topic {topic_name}: {e}")
                                                                  ^
NameError: name 'e' is not defined
[2024-11-30T20:35:34.004+0000] {taskinstance.py:1206} INFO - Marking task as UP_FOR_RETRY. dag_id=weather_data_kafka_dag, task_id=store_openmeteo_data, run_id=scheduled__2024-11-30T16:00:00+00:00, execution_date=20241130T160000, start_date=20241130T203532, end_date=20241130T203534
[2024-11-30T20:35:34.128+0000] {standard_task_runner.py:110} ERROR - Failed to execute job 447 for task store_openmeteo_data (name 'e' is not defined; 17315)
[2024-11-30T20:35:34.159+0000] {local_task_job_runner.py:243} INFO - Task exited with return code 1
[2024-11-30T20:35:34.205+0000] {taskinstance.py:3503} INFO - 0 downstream tasks scheduled from follow-on schedule check
[2024-11-30T20:35:34.255+0000] {local_task_job_runner.py:222} INFO - ::endgroup::
